<mujoco model="sda10f">
  <compiler angle="radian" meshdir="motoman/meshes/" autolimits="true" inertiafromgeom="true" balanceinertia="true"/>
  <default>
    <position kp="10000000000000000" forcerange="-42 42"/>
    <velocity kv="10000000000000" forcerange="-42 42" ctrlrange="-2.2 2.2"/>
    <default class="RB">
      <position forcerange="-30 30"/>
      <velocity forcerange="-30 30" ctrlrange="-3.4 3.4"/>
    </default>
    <default class="T">
      <position forcerange="-18 18"/>
      <velocity forcerange="-18 18" ctrlrange="-6.9 6.9"/>
    </default>
    <default class="hidden">
      <geom group="3"/>
      <joint armature="0.1" damping="50"/>
    </default>
    <default class="2f85">
      <mesh scale="0.001 0.001 0.001"/>
      <general biastype="affine"/>
      <joint axis="1 0 0" />
      <!-- <joint axis="1 0 0" armature="0" damping="0"/> -->
      <default class="driver">
        <joint range="0 0.8" armature="0.005" damping="0.1" solimplimit="0.95 0.99 0.001"
          solreflimit="0.005 1"/>
      </default>
      <default class="follower">
        <joint range="-0.872664 0.872664" pos="0 -0.018 0.0065" solimplimit="0.95 0.99 0.001"
          solreflimit="0.005 1"/>
      </default>
      <default class="spring_link">
        <joint range="-0.29670597283 0.8" stiffness="0.05" springref="2.62" damping="0.00125"/>
      </default>
      <default class="coupler">
        <joint range="-1.57 0" solimplimit="0.95 0.99 0.001" solreflimit="0.005 1"/>
      </default>
      <default class="visual">
        <geom type="mesh" contype="0" conaffinity="0" group="1"/>
      </default>
      <default class="collision">
        <geom type="mesh" group="3"/>
        <default class="pad_box1">
          <geom mass="0" type="box" pos="0 -0.0026 0.028125" size="0.011 0.004 0.009375"
            friction="0.7" solimp="0.95 0.99 0.001" solref="0.004 1" priority="1"
            rgba="0.55 0.55 0.55 1"/>
        </default>
        <default class="pad_box2">
          <geom mass="0" type="box" pos="0 -0.0026 0.009375" size="0.011 0.004 0.009375"
            friction="0.6" solimp="0.95 0.99 0.001" solref="0.004 1" priority="1"
            rgba="0.45 0.45 0.45 1"/>
        </default>
      </default>
    </default>
  </default>
  <asset>
    <mesh name="motoman_base_v" file="motoman_base_v.stl"/>
    <mesh name="motoman_base" file="motoman_base.stl"/>
    <mesh name="motoman_axis_b1_v" file="motoman_axis_b1_v.stl"/>
    <mesh name="motoman_axis_b1_remeshed" file="motoman_axis_b1_remeshed.stl"/>
    <mesh name="motoman_axis_s_v" file="motoman_axis_s_v.stl"/>
    <mesh name="motoman_axis_s" file="motoman_axis_s.stl"/>
    <mesh name="motoman_axis_l_v" file="motoman_axis_l_v.stl"/>
    <mesh name="motoman_axis_l" file="motoman_axis_l.stl"/>
    <mesh name="motoman_axis_e_v" file="motoman_axis_e_v.stl"/>
    <mesh name="motoman_axis_e" file="motoman_axis_e.stl"/>
    <mesh name="motoman_axis_u_v" file="motoman_axis_u_v.stl"/>
    <mesh name="motoman_axis_u" file="motoman_axis_u.stl"/>
    <mesh name="motoman_axis_r_v" file="motoman_axis_r_v.stl"/>
    <mesh name="motoman_axis_r" file="motoman_axis_r.stl"/>
    <mesh name="motoman_axis_b_v" file="motoman_axis_b_v.stl"/>
    <mesh name="motoman_axis_b_remeshed" file="motoman_axis_b_remeshed.stl"/>
    <mesh name="motoman_axis_t_v" file="motoman_axis_t_v.stl"/>
    <mesh name="motoman_axis_t" file="motoman_axis_t.stl"/>
    <mesh name="base_link_v" file="base_link_v.stl"/>
    <mesh name="base_link" file="base_link.stl"/>
    <mesh name="suction_cup_v" file="suction_cup_v.stl"/>
    <mesh name="suction_cup" file="suction_cup.stl"/>

    <material name="metal" rgba="0.58 0.58 0.58 1"/>
    <material name="silicone" rgba="0.1882 0.1882 0.1882 1"/>
    <material name="gray" rgba="0.4627 0.4627 0.4627 1"/>
    <material name="black" rgba="0.149 0.149 0.149 1"/>

    <mesh class="2f85" file="base_mount.stl"/>
    <mesh class="2f85" file="base.stl"/>
    <mesh class="2f85" file="driver.stl"/>
    <mesh class="2f85" file="coupler.stl"/>
    <mesh class="2f85" file="follower.stl"/>
    <mesh class="2f85" file="pad.stl"/>
    <mesh class="2f85" file="silicone_pad.stl"/>
    <mesh class="2f85" file="spring_link.stl"/>
  </asset>
  <worldbody>
    <body name="motoman_base" childclass="hidden">
      <geom type="mesh" contype="0" conaffinity="0" group="1" density="0" rgba="0 0 1 1" mesh="motoman_base_v"/>
      <geom type="mesh" rgba="0 0 1 1" mesh="motoman_base"/>
      <body name="torso_link_b1" pos="0.09257 0 0.877" gravcomp="0">
        <inertial pos="0.297696 -0.00048507 0.0755602" quat="0 0.555263 0 0.831675" mass="0.0255703" diaginertia="0.000518781 0.00050765 0.000236609"/>
        <joint name="torso_joint_b1" pos="0 0 0" axis="0 0 1" range="-1.58 1.58"/>
        <geom type="mesh" contype="0" conaffinity="0" group="1" density="0" rgba="0.8 0.8 0.8 1" mesh="motoman_axis_b1_v"/>
        <geom type="mesh" rgba="0.8 0.8 0.8 1" mesh="motoman_axis_b1_remeshed"/>
        <body name="arm_left_link_1_s" pos="0.09996 0.0375 0.32214" quat="0.707388 0.706825 0 0" gravcomp="0">
          <inertial pos="-0.198992 -0.0506283 -0.00088638" quat="0.218923 0.639794 0.30116 0.672339" mass="0.00736469" diaginertia="6.63287e-05 6.62889e-05 2.86024e-05"/>
          <joint name="arm_left_joint_1_s" pos="0 0 0" axis="0 0 -1" range="-3.13 3.13"/>
          <geom type="mesh" contype="0" conaffinity="0" group="1" density="0" rgba="0 0 1 1" mesh="motoman_axis_s_v"/>
          <geom type="mesh" rgba="0 0 1 1" mesh="motoman_axis_s"/>
          <body name="arm_left_link_2_l" pos="0 0.0427 -0.2255" quat="0.707388 -0.706825 0 0" gravcomp="0">
            <inertial pos="0.00687143 0.0134517 0.00026218" quat="0.699912 0.699912 0.100612 0.100612" mass="0.00447593" diaginertia="3.37074e-05 3.068e-05 1.20626e-05"/>
            <joint name="arm_left_joint_2_l" pos="0 0 0" axis="0 0 -1" range="-1.9 1.9"/>
            <geom type="mesh" contype="0" conaffinity="0" group="1" density="0" rgba="0.8 0.8 0.8 1" mesh="motoman_axis_l_v"/>
            <geom type="mesh" rgba="0.8 0.8 0.8 1" mesh="motoman_axis_l"/>
            <body name="arm_left_link_3_e" pos="0 0.179 -0.0454" quat="0.707388 0.706825 0 0" gravcomp="0">
              <inertial pos="-0.146998 0.0392846 -0.00115009" quat="0.533046 0.533046 0.46461 0.46461" mass="0.00344203" diaginertia="1.93323e-05 1.927e-05 7.94772e-06"/>
              <joint name="arm_left_joint_3_e" pos="0 0 0" axis="0 0 -1" range="-2.95 2.95"/>
              <geom type="mesh" contype="0" conaffinity="0" group="1" density="0" rgba="0 0 1 1" mesh="motoman_axis_e_v"/>
              <geom type="mesh" rgba="0 0 1 1" mesh="motoman_axis_e"/>
              <body name="arm_left_link_4_u" pos="0 -0.0175 -0.181" quat="0.707388 -0.706825 0 0" gravcomp="0">
                <inertial pos="-0.0149121 0.0471967 -0.00082991" quat="0.704896 0.705064 -0.0617056 -0.0468954" mass="0.00301532" diaginertia="2.11237e-05 2.04297e-05 5.19652e-06"/>
                <joint name="arm_left_joint_4_u" pos="0 0 0" axis="0 0 1" range="-2.36 2.36"/>
                <geom type="mesh" contype="0" conaffinity="0" group="1" density="0" rgba="0.8 0.8 0.8 1" mesh="motoman_axis_u_v"/>
                <geom type="mesh" rgba="0.8 0.8 0.8 1" mesh="motoman_axis_u"/>
                <body name="arm_left_link_5_r" pos="0 0.2036 0.0155" quat="0.707388 0.706825 0 0" gravcomp="0">
                  <inertial pos="-0.117624 -0.0312851 -0.00026296" quat="-0.0883248 0.705508 0.013644 0.703044" mass="0.00213955" diaginertia="8.73083e-06 8.66389e-06 3.60528e-06"/>
                  <joint name="arm_left_joint_5_r" pos="0 0 0" axis="0 0 1" range="-3.13 3.13"/>
                  <geom type="mesh" contype="0" conaffinity="0" group="1" density="0" rgba="0 0 1 1" mesh="motoman_axis_r_v"/>
                  <geom type="mesh" rgba="0 0 1 1" mesh="motoman_axis_r"/>
                  <body name="arm_left_link_6_b" pos="0 0.013 -0.155" quat="0.707388 -0.706825 0 0" gravcomp="0">
                    <inertial pos="0.0125445 0.0235749 -0.00200508" quat="0.702555 0.702555 0.0801062 0.0801062" mass="0.00182883" diaginertia="7.26798e-06 7.09e-06 2.57202e-06"/>
                    <joint name="arm_left_joint_6_b" pos="0 0 0" axis="0 0 1" range="-1.9 1.9"/>
                    <geom type="mesh" contype="0" conaffinity="0" group="1" density="0" rgba="0.8 0.8 0.8 1" mesh="motoman_axis_b_v"/>
                    <geom type="mesh" rgba="0.8 0.8 0.8 1" mesh="motoman_axis_b_remeshed"/>
                    <body name="arm_left_link_7_t" pos="0 0.144 -0.015" quat="0.707388 0.706825 0 0" gravcomp="0">
                      <joint name="arm_left_joint_7_t" pos="0 0 0" axis="0 0 1" range="-3.13 3.13"/>
                      <geom type="mesh" contype="0" conaffinity="0" group="1" density="0" rgba="0 0 1 1" mesh="motoman_axis_t_v"/>
                      <geom type="mesh" rgba="0 0 1 1" mesh="motoman_axis_t"/>
                      <geom pos="0 0 -0.035" quat="-2.1291e-08 0.00579629 -0.999983 3.67314e-06" type="mesh" contype="0" conaffinity="0" group="1" density="0" rgba="0 0 1 1" mesh="base_link_v"/>
                      <geom pos="0 0 -0.035" quat="-2.1291e-08 0.00579629 -0.999983 3.67314e-06" type="mesh" rgba="0 0 1 1" mesh="base_link"/>
                      <geom pos="8.082e-09 -6.97135e-07 -0.129901" quat="-2.1291e-08 0.00579629 -0.999983 3.67314e-06" type="mesh" contype="0" conaffinity="0" group="1" density="0" rgba="0 0 1 1" mesh="suction_cup_v"/>
                      <geom pos="8.082e-09 -6.97135e-07 -0.129901" quat="-2.1291e-08 0.00579629 -0.999983 3.67314e-06" type="mesh" rgba="0 0 1 1" mesh="suction_cup"/>
                      <body name="EE_left" pos="0 0 -0.21" euler="0 0 0">
                        <geom type="box" size="0.02 0.02 0.01" group="1" margin="0.02" gap="0.02" pos="0 0 0.005" mass="0.00001"/>
                      </body>
                    </body>
                  </body>
                </body>
              </body>
            </body>
          </body>
        </body>
        <body name="arm_right_link_1_s" pos="0.09996 -0.0375 0.32214" quat="0.000563312 0.000562864 -0.706825 -0.707388" gravcomp="0">
          <inertial pos="-0.198992 -0.0506283 -0.00088638" quat="0.218923 0.639794 0.30116 0.672339" mass="0.00736469" diaginertia="6.63287e-05 6.62889e-05 2.86024e-05"/>
          <joint name="arm_right_joint_1_s" pos="0 0 0" axis="0 0 1" range="-3.13 3.13"/>
          <geom type="mesh" contype="0" conaffinity="0" group="1" density="0" rgba="0 0 1 1" mesh="motoman_axis_s_v"/>
          <geom type="mesh" rgba="0 0 1 1" mesh="motoman_axis_s"/>
          <body name="arm_right_link_2_l" pos="0 0.0427 -0.2255" quat="0.707388 -0.706825 0 0" gravcomp="0">
            <inertial pos="0.00687143 0.0134517 0.00026218" quat="0.699912 0.699912 0.100612 0.100612" mass="0.00447593" diaginertia="3.37074e-05 3.068e-05 1.20626e-05"/>
            <joint name="arm_right_joint_2_l" pos="0 0 0" axis="0 0 1" range="-1.9 1.9"/>
            <geom type="mesh" contype="0" conaffinity="0" group="1" density="0" rgba="0.8 0.8 0.8 1" mesh="motoman_axis_l_v"/>
            <geom type="mesh" rgba="0.8 0.8 0.8 1" mesh="motoman_axis_l"/>
            <body name="arm_right_link_3_e" pos="0 0.179 -0.0454" quat="0.707388 0.706825 0 0" gravcomp="0">
              <inertial pos="-0.146998 0.0392846 -0.00115009" quat="0.533046 0.533046 0.46461 0.46461" mass="0.00344203" diaginertia="1.93323e-05 1.927e-05 7.94772e-06"/>
              <joint name="arm_right_joint_3_e" pos="0 0 0" axis="0 0 1" range="-2.95 2.95"/>
              <geom type="mesh" contype="0" conaffinity="0" group="1" density="0" rgba="0 0 1 1" mesh="motoman_axis_e_v"/>
              <geom type="mesh" rgba="0 0 1 1" mesh="motoman_axis_e"/>
              <body name="arm_right_link_4_u" pos="0 -0.0175 -0.181" quat="0.707388 -0.706825 0 0" gravcomp="0">
                <inertial pos="-0.0149121 0.0471967 -0.00082991" quat="0.704896 0.705064 -0.0617056 -0.0468954" mass="0.00301532" diaginertia="2.11237e-05 2.04297e-05 5.19652e-06"/>
                <joint name="arm_right_joint_4_u" pos="0 0 0" axis="0 0 -1" range="-2.36 2.36"/>
                <geom type="mesh" contype="0" conaffinity="0" group="1" density="0" rgba="0.8 0.8 0.8 1" mesh="motoman_axis_u_v"/>
                <geom type="mesh" rgba="0.8 0.8 0.8 1" mesh="motoman_axis_u"/>
                <body name="arm_right_link_5_r" pos="0 0.2036 0.0155" quat="0.707388 0.706825 0 0" gravcomp="0">
                  <inertial pos="-0.117624 -0.0312851 -0.00026296" quat="-0.0883248 0.705508 0.013644 0.703044" mass="0.00213955" diaginertia="8.73083e-06 8.66389e-06 3.60528e-06"/>
                  <joint name="arm_right_joint_5_r" pos="0 0 0" axis="0 0 -1" range="-3.13 3.13"/>
                  <geom type="mesh" contype="0" conaffinity="0" group="1" density="0" rgba="0 0 1 1" mesh="motoman_axis_r_v"/>
                  <geom type="mesh" rgba="0 0 1 1" mesh="motoman_axis_r"/>
                  <body name="arm_right_link_6_b" pos="0 0.013 -0.155" quat="0.707388 -0.706825 0 0" gravcomp="0">
                    <inertial pos="0.0125445 0.0235749 -0.00200508" quat="0.702555 0.702555 0.0801062 0.0801062" mass="0.00182883" diaginertia="7.26798e-06 7.09e-06 2.57202e-06"/>
                    <joint name="arm_right_joint_6_b" pos="0 0 0" axis="0 0 -1" range="-1.9 1.9"/>
                    <geom type="mesh" contype="0" conaffinity="0" group="1" density="0" rgba="0.8 0.8 0.8 1" mesh="motoman_axis_b_v"/>
                    <geom type="mesh" rgba="0.8 0.8 0.8 1" mesh="motoman_axis_b_remeshed"/>
                    <body name="arm_right_link_7_t" pos="0 0.144 -0.015" quat="0.707388 0.706825 0 0" gravcomp="0">
                      <joint name="arm_right_joint_7_t" pos="0 0 0" axis="0 0 -1" range="-3.13 3.13"/>
                      <geom type="mesh" contype="0" conaffinity="0" group="1" density="0" rgba="0 0 1 1" mesh="motoman_axis_t_v"/>
                      <geom type="mesh" rgba="0 0 1 1" mesh="motoman_axis_t"/>
                      <body name="robotiq_2f85" zaxis="0 0 -1" pos="0 0 -0.0275">
                        <body name="base_mount" pos="0 0 0.007" childclass="2f85">
                          <geom class="visual" mesh="base_mount" material="black"/>
                          <geom class="collision" mesh="base_mount"/>
                          <body name="base" pos="0 0 0.0038" quat="1 0 0 -1">
                            <inertial mass="0.777441" pos="0 -2.70394e-05 0.0354675" quat="1 -0.00152849 0 0"
                              diaginertia="0.000260285 0.000225381 0.000152708"/>
                            <geom class="visual" mesh="base" material="black"/>
                            <geom class="collision" mesh="base"/>
                              <!-- Right-hand side 4-bar linkage -->
                            <body name="right_driver" pos="0 0.0306011 0.054904">
                              <inertial mass="0.00899563" pos="2.96931e-12 0.0177547 0.00107314"
                                quat="0.681301 0.732003 0 0" diaginertia="1.72352e-06 1.60906e-06 3.22006e-07"/>
                              <joint name="right_driver_joint" class="driver"/>
                              <geom class="visual" mesh="driver" material="gray"/>
                              <geom class="collision" mesh="driver"/>
                              <body name="right_coupler" pos="0 0.0315 -0.0041">
                                <inertial mass="0.0140974" pos="0 0.00301209 0.0232175"
                                  quat="0.705636 -0.0455904 0.0455904 0.705636"
                                  diaginertia="4.16206e-06 3.52216e-06 8.88131e-07"/>
                                <joint name="right_coupler_joint" class="coupler"/>
                                <geom class="visual" mesh="coupler" material="black"/>
                                <geom class="collision" mesh="coupler"/>
                              </body>
                            </body>
                            <body name="right_spring_link" pos="0 0.0132 0.0609">
                              <inertial mass="0.0221642" pos="-8.65005e-09 0.0181624 0.0212658"
                                quat="0.663403 -0.244737 0.244737 0.663403"
                                diaginertia="8.96853e-06 6.71733e-06 2.63931e-06"/>
                              <joint name="right_spring_link_joint" class="spring_link"/>
                              <geom class="visual" mesh="spring_link" material="black"/>
                              <geom class="collision" mesh="spring_link"/>
                              <body name="right_follower" pos="0 0.055 0.0375">
                                <inertial mass="0.0125222" pos="0 -0.011046 0.0124786" quat="1 0.1664 0 0"
                                  diaginertia="2.67415e-06 2.4559e-06 6.02031e-07"/>
                                <joint name="right_follower_joint" class="follower"/>
                                <geom class="visual" mesh="follower" material="black"/>
                                <geom class="collision" mesh="follower"/>
                                <body name="right_pad" pos="0 -0.0189 0.01352">
                                  <geom class="pad_box1"/>
                                  <geom class="pad_box2"/>
                                  <inertial mass="0.0035" pos="0 -0.0025 0.0185" quat="0.707107 0 0 0.707107"
                                    diaginertia="4.73958e-07 3.64583e-07 1.23958e-07"/>
                                  <geom class="visual" mesh="pad"/>
                                  <body name="right_silicone_pad">
                                    <geom class="visual" mesh="silicone_pad" material="black"/>
                                  </body>
                                </body>
                              </body>
                            </body>
                            <!-- Left-hand side 4-bar linkage -->
                            <body name="left_driver" pos="0 -0.0306011 0.054904" quat="0 0 0 1">
                              <inertial mass="0.00899563" pos="0 0.0177547 0.00107314" quat="0.681301 0.732003 0 0"
                                diaginertia="1.72352e-06 1.60906e-06 3.22006e-07"/>
                              <joint name="left_driver_joint" class="driver"/>
                              <geom class="visual" mesh="driver" material="gray"/>
                              <geom class="collision" mesh="driver"/>
                              <body name="left_coupler" pos="0 0.0315 -0.0041">
                                <inertial mass="0.0140974" pos="0 0.00301209 0.0232175"
                                  quat="0.705636 -0.0455904 0.0455904 0.705636"
                                  diaginertia="4.16206e-06 3.52216e-06 8.88131e-07"/>
                                <joint name="left_coupler_joint" class="coupler"/>
                                <geom class="visual" mesh="coupler" material="black"/>
                                <geom class="collision" mesh="coupler"/>
                              </body>
                            </body>
                            <body name="left_spring_link" pos="0 -0.0132 0.0609" quat="0 0 0 1">
                              <inertial mass="0.0221642" pos="-8.65005e-09 0.0181624 0.0212658"
                                quat="0.663403 -0.244737 0.244737 0.663403"
                                diaginertia="8.96853e-06 6.71733e-06 2.63931e-06"/>
                              <joint name="left_spring_link_joint" class="spring_link"/>
                              <geom class="visual" mesh="spring_link" material="black"/>
                              <geom class="collision" mesh="spring_link"/>
                              <body name="left_follower" pos="0 0.055 0.0375">
                                <inertial mass="0.0125222" pos="0 -0.011046 0.0124786" quat="1 0.1664 0 0"
                                  diaginertia="2.67415e-06 2.4559e-06 6.02031e-07"/>
                                <joint name="left_follower_joint" class="follower"/>
                                <geom class="visual" mesh="follower" material="black"/>
                                <geom class="collision" mesh="follower"/>
                                <body name="left_pad" pos="0 -0.0189 0.01352">
                                  <geom class="pad_box1"/>
                                  <geom class="pad_box2"/>
                                  <inertial mass="0.0035" pos="0 -0.0025 0.0185" quat="1 0 0 1"
                                    diaginertia="4.73958e-07 3.64583e-07 1.23958e-07"/>
                                  <geom class="visual" mesh="pad"/>
                                  <body name="left_silicone_pad">
                                    <geom class="visual" mesh="silicone_pad" material="black"/>
                                  </body>
                                </body>
                              </body>
                            </body>
                          </body>
                        </body>
                      </body>
                      <body name="EE_right" pos="0 0 -0.18" euler="0 0 0"/>
                    </body>
                  </body>
                </body>
              </body>
            </body>
          </body>
        </body>
      </body>
    </body>
  </worldbody>

  <contact>
    <exclude body1="base" body2="left_driver"/>
    <exclude body1="base" body2="right_driver"/>
    <exclude body1="base" body2="left_spring_link"/>
    <exclude body1="base" body2="right_spring_link"/>
    <exclude body1="right_coupler" body2="right_follower"/>
    <exclude body1="left_coupler" body2="left_follower"/>
  </contact>
  <!--
    This adds stability to the model by having a tendon that distributes the forces between both
    joints, such that the equality constraint doesn't have to do that much work in order to equalize
    both joints. Since both joints share the same sign, we split the force between both equally by
    setting coef=0.5
  -->
  <tendon>
    <fixed name="split">
      <joint joint="right_driver_joint" coef="0.5"/>
      <joint joint="left_driver_joint" coef="0.5"/>
    </fixed>
  </tendon>

  <equality>
    <connect anchor="0 0 0" body1="right_follower" body2="right_coupler" solimp="0.95 0.99 0.001"
      solref="0.005 1"/>
    <connect anchor="0 0 0" body1="left_follower" body2="left_coupler" solimp="0.95 0.99 0.001"
      solref="0.005 1"/>
    <joint joint1="right_driver_joint" joint2="left_driver_joint" polycoef="0 1 0 0 0"
      solimp="0.95 0.99 0.001" solref="0.005 1"/>
  </equality>

  <actuator>
    <adhesion name="suction" body="EE_left" ctrlrange="0 1" gain="80"/>
      <!--
        The general actuator below is a customized position actuator (with some damping) where
        gainprm[0] != kp (see http://mujoco.org/book/modeling.html#position).
        The reason why gainprm[0] != kp is because the control input range has to be re-scaled to
        [0, 255]. The joint range is currently set at [0, 0.8], the control range is [0, 255] and
        kp = 100. Tau = Kp * scale * control_input - Kp * error, max(Kp * scale * control_input) = 0.8,
        hence scale = 0.8 * 100 / 255
      -->
    <general class="2f85" name="fingers_actuator" tendon="split" forcerange="-5 5"
      ctrlrange="0 255" gainprm="0.3137255 0 0" biasprm="0 -100 -10"/>

    <position name="torso_b1" joint="torso_joint_b1" ctrlrange="-1.58 1.58"/>
    <position name="arm_left_1_s" joint="arm_left_joint_1_s" ctrlrange="-3.13 3.13"/>
    <position name="arm_left_2_l" joint="arm_left_joint_2_l" ctrlrange="-1.9 1.9"/>
    <position name="arm_left_3_e" joint="arm_left_joint_3_e" ctrlrange="-2.95 2.95"/>
    <position name="arm_left_4_u" joint="arm_left_joint_4_u" ctrlrange="-2.36 2.36"/>
    <position name="arm_left_5_r" joint="arm_left_joint_5_r" ctrlrange="-3.13 3.13" class="RB"/>
    <position name="arm_left_6_b" joint="arm_left_joint_6_b" ctrlrange="-1.9 1.9" class="RB"/>
    <position name="arm_left_7_t" joint="arm_left_joint_7_t" ctrlrange="-3.13 3.13" class="T"/>
    <position name="arm_right_1_s" joint="arm_right_joint_1_s" ctrlrange="-3.13 3.13"/>
    <position name="arm_right_2_l" joint="arm_right_joint_2_l" ctrlrange="-1.9 1.9"/>
    <position name="arm_right_3_e" joint="arm_right_joint_3_e" ctrlrange="-2.95 2.95"/>
    <position name="arm_right_4_u" joint="arm_right_joint_4_u" ctrlrange="-2.36 2.36"/>
    <position name="arm_right_5_r" joint="arm_right_joint_5_r" ctrlrange="-3.13 3.13" class="RB"/>
    <position name="arm_right_6_b" joint="arm_right_joint_6_b" ctrlrange="-1.9 1.9" class="RB"/>
    <position name="arm_right_7_t" joint="arm_right_joint_7_t" ctrlrange="-3.13 3.13" class="T"/>

    <velocity name="torso_v_b1" joint="torso_joint_b1" />
    <velocity name="arm_left_v_1_s" joint="arm_left_joint_1_s" />
    <velocity name="arm_left_v_2_l" joint="arm_left_joint_2_l" />
    <velocity name="arm_left_v_3_e" joint="arm_left_joint_3_e" />
    <velocity name="arm_left_v_4_u" joint="arm_left_joint_4_u" />
    <velocity name="arm_left_v_5_r" joint="arm_left_joint_5_r" class="RB"/>
    <velocity name="arm_left_v_6_b" joint="arm_left_joint_6_b" class="RB"/>
    <velocity name="arm_left_v_7_t" joint="arm_left_joint_7_t" class="T"/>
    <velocity name="arm_right_v_1_s" joint="arm_right_joint_1_s" />
    <velocity name="arm_right_v_2_l" joint="arm_right_joint_2_l" />
    <velocity name="arm_right_v_3_e" joint="arm_right_joint_3_e" />
    <velocity name="arm_right_v_4_u" joint="arm_right_joint_4_u" />
    <velocity name="arm_right_v_5_r" joint="arm_right_joint_5_r" class="RB"/>
    <velocity name="arm_right_v_6_b" joint="arm_right_joint_6_b" class="RB"/>
    <velocity name="arm_right_v_7_t" joint="arm_right_joint_7_t" class="T"/>

    <!-- <intvelocity kp="200" forcerange="-100 100" name="torso_v_b1" joint="torso_joint_b1" actrange="-1.58 1.58"/> -->
    <!-- <intvelocity kp="200" forcerange="-100 100" name="arm_left_v_1_s" joint="arm_left_joint_1_s" actrange="-3.13 3.13"/> -->
    <!-- <intvelocity kp="200" forcerange="-100 100" name="arm_left_v_2_l" joint="arm_left_joint_2_l" actrange="-1.9 1.9"/> -->
    <!-- <intvelocity kp="200" forcerange="-100 100" name="arm_left_v_3_e" joint="arm_left_joint_3_e" actrange="-2.95 2.95"/> -->
    <!-- <intvelocity kp="200" forcerange="-100 100" name="arm_left_v_4_u" joint="arm_left_joint_4_u" actrange="-2.36 2.36"/> -->
    <!-- <intvelocity kp="200" forcerange="-100 100" name="arm_left_v_5_r" joint="arm_left_joint_5_r" actrange="-3.13 3.13"/> -->
    <!-- <intvelocity kp="200" forcerange="-100 100" name="arm_left_v_6_b" joint="arm_left_joint_6_b" actrange="-1.9 1.9"/> -->
    <!-- <intvelocity kp="200" forcerange="-100 100" name="arm_left_v_7_t" joint="arm_left_joint_7_t" actrange="-3.13 3.13"/> -->
    <!-- <intvelocity kp="200" forcerange="-100 100" name="arm_right_v_1_s" joint="arm_right_joint_1_s" actrange="-3.13 3.13"/> -->
    <!-- <intvelocity kp="200" forcerange="-100 100" name="arm_right_v_2_l" joint="arm_right_joint_2_l" actrange="-1.9 1.9"/> -->
    <!-- <intvelocity kp="200" forcerange="-100 100" name="arm_right_v_3_e" joint="arm_right_joint_3_e" actrange="-2.95 2.95"/> -->
    <!-- <intvelocity kp="200" forcerange="-100 100" name="arm_right_v_4_u" joint="arm_right_joint_4_u" actrange="-2.36 2.36"/> -->
    <!-- <intvelocity kp="200" forcerange="-100 100" name="arm_right_v_5_r" joint="arm_right_joint_5_r" actrange="-3.13 3.13"/> -->
    <!-- <intvelocity kp="200" forcerange="-100 100" name="arm_right_v_6_b" joint="arm_right_joint_6_b" actrange="-1.9 1.9"/> -->
    <!-- <intvelocity kp="200" forcerange="-100 100" name="arm_right_v_7_t" joint="arm_right_joint_7_t" actrange="-3.13 3.13"/> -->

  </actuator>
</mujoco>
