<mujoco model="sda10f">
  <compiler angle="radian" meshdir="meshes/" autolimits="true" inertiafromgeom="true" balanceinertia="true"/>
  <default class="hidden">
    <geom group="3"/>
  </default>
  <asset>
    <mesh name="motoman_base_v" file="motoman_base_v.stl"/>
    <mesh name="motoman_base" file="motoman_base.stl"/>
    <mesh name="motoman_axis_b1_v" file="motoman_axis_b1_v.stl"/>
    <mesh name="motoman_axis_b1_remeshed" file="motoman_axis_b1_remeshed.stl"/>
    <mesh name="motoman_axis_s_v" file="motoman_axis_s_v.stl"/>
    <mesh name="motoman_axis_s" file="motoman_axis_s.stl"/>
    <mesh name="motoman_axis_l_v" file="motoman_axis_l_v.stl"/>
    <mesh name="motoman_axis_l" file="motoman_axis_l.stl"/>
    <mesh name="motoman_axis_e_v" file="motoman_axis_e_v.stl"/>
    <mesh name="motoman_axis_e" file="motoman_axis_e.stl"/>
    <mesh name="motoman_axis_u_v" file="motoman_axis_u_v.stl"/>
    <mesh name="motoman_axis_u" file="motoman_axis_u.stl"/>
    <mesh name="motoman_axis_r_v" file="motoman_axis_r_v.stl"/>
    <mesh name="motoman_axis_r" file="motoman_axis_r.stl"/>
    <mesh name="motoman_axis_b_v" file="motoman_axis_b_v.stl"/>
    <mesh name="motoman_axis_b_remeshed" file="motoman_axis_b_remeshed.stl"/>
    <mesh name="motoman_axis_t_v" file="motoman_axis_t_v.stl"/>
    <mesh name="motoman_axis_t" file="motoman_axis_t.stl"/>
    <mesh name="base_link_v" file="base_link_v.stl"/>
    <mesh name="base_link" file="base_link.stl"/>
    <mesh name="suction_cup_v" file="suction_cup_v.stl"/>
    <mesh name="suction_cup" file="suction_cup.stl"/>
    <mesh name="robotiq_arg2f_85_base_link_v" file="robotiq_arg2f_85_base_link_v.stl" scale="0.001 0.001 0.001"/>
    <mesh name="robotiq_arg2f_base_link" file="robotiq_arg2f_base_link.stl"/>
    <mesh name="robotiq_arg2f_85_outer_knuckle_v" file="robotiq_arg2f_85_outer_knuckle_v.stl" scale="0.001 0.001 0.001"/>
    <mesh name="robotiq_arg2f_85_outer_knuckle" file="robotiq_arg2f_85_outer_knuckle.stl" scale="0.001 0.001 0.001"/>
    <mesh name="robotiq_arg2f_85_outer_finger_v" file="robotiq_arg2f_85_outer_finger_v.stl" scale="0.001 0.001 0.001"/>
    <mesh name="robotiq_arg2f_85_outer_finger" file="robotiq_arg2f_85_outer_finger.stl" scale="0.001 0.001 0.001"/>
    <mesh name="robotiq_arg2f_85_inner_finger_v" file="robotiq_arg2f_85_inner_finger_v.stl" scale="0.001 0.001 0.001"/>
    <mesh name="robotiq_arg2f_85_inner_finger" file="robotiq_arg2f_85_inner_finger.stl" scale="0.001 0.001 0.001"/>
    <mesh name="robotiq_arg2f_85_inner_knuckle_v" file="robotiq_arg2f_85_inner_knuckle_v.stl" scale="0.001 0.001 0.001"/>
    <mesh name="robotiq_arg2f_85_inner_knuckle" file="robotiq_arg2f_85_inner_knuckle.stl" scale="0.001 0.001 0.001"/>
  </asset>
  <worldbody>
    <body childclass="hidden">
      <geom type="mesh" contype="0" conaffinity="0" group="1" density="0" rgba="0 0 1 1" mesh="motoman_base_v"/>
      <geom type="mesh" rgba="0 0 1 1" mesh="motoman_base"/>
      <body name="torso_link_b1" pos="0.09257 0 0.877" gravcomp="0">
        <inertial pos="0.297696 -0.00048507 0.0755602" quat="0 0.555263 0 0.831675" mass="0.0255703" diaginertia="0.000518781 0.00050765 0.000236609"/>
        <joint name="torso_joint_b1" pos="0 0 0" axis="0 0 1" range="-1.58 1.58"/>
        <geom type="mesh" contype="0" conaffinity="0" group="1" density="0" rgba="0.8 0.8 0.8 1" mesh="motoman_axis_b1_v"/>
        <geom type="mesh" rgba="0.8 0.8 0.8 1" mesh="motoman_axis_b1_remeshed"/>
        <body name="arm_left_link_1_s" pos="0.09996 0.0375 0.32214" quat="0.707388 0.706825 0 0" gravcomp="0">
          <inertial pos="-0.198992 -0.0506283 -0.00088638" quat="0.218923 0.639794 0.30116 0.672339" mass="0.00736469" diaginertia="6.63287e-05 6.62889e-05 2.86024e-05"/>
          <joint name="arm_left_joint_1_s" pos="0 0 0" axis="0 0 -1" range="-3.13 3.13"/>
          <geom type="mesh" contype="0" conaffinity="0" group="1" density="0" rgba="0 0 1 1" mesh="motoman_axis_s_v"/>
          <geom type="mesh" rgba="0 0 1 1" mesh="motoman_axis_s"/>
          <body name="arm_left_link_2_l" pos="0 0.0427 -0.2255" quat="0.707388 -0.706825 0 0" gravcomp="0">
            <inertial pos="0.00687143 0.0134517 0.00026218" quat="0.699912 0.699912 0.100612 0.100612" mass="0.00447593" diaginertia="3.37074e-05 3.068e-05 1.20626e-05"/>
            <joint name="arm_left_joint_2_l" pos="0 0 0" axis="0 0 -1" range="-1.9 1.9"/>
            <geom type="mesh" contype="0" conaffinity="0" group="1" density="0" rgba="0.8 0.8 0.8 1" mesh="motoman_axis_l_v"/>
            <geom type="mesh" rgba="0.8 0.8 0.8 1" mesh="motoman_axis_l"/>
            <body name="arm_left_link_3_e" pos="0 0.179 -0.0454" quat="0.707388 0.706825 0 0" gravcomp="0">
              <inertial pos="-0.146998 0.0392846 -0.00115009" quat="0.533046 0.533046 0.46461 0.46461" mass="0.00344203" diaginertia="1.93323e-05 1.927e-05 7.94772e-06"/>
              <joint name="arm_left_joint_3_e" pos="0 0 0" axis="0 0 -1" range="-2.95 2.95"/>
              <geom type="mesh" contype="0" conaffinity="0" group="1" density="0" rgba="0 0 1 1" mesh="motoman_axis_e_v"/>
              <geom type="mesh" rgba="0 0 1 1" mesh="motoman_axis_e"/>
              <body name="arm_left_link_4_u" pos="0 -0.0175 -0.181" quat="0.707388 -0.706825 0 0" gravcomp="0">
                <inertial pos="-0.0149121 0.0471967 -0.00082991" quat="0.704896 0.705064 -0.0617056 -0.0468954" mass="0.00301532" diaginertia="2.11237e-05 2.04297e-05 5.19652e-06"/>
                <joint name="arm_left_joint_4_u" pos="0 0 0" axis="0 0 1" range="-2.36 2.36"/>
                <geom type="mesh" contype="0" conaffinity="0" group="1" density="0" rgba="0.8 0.8 0.8 1" mesh="motoman_axis_u_v"/>
                <geom type="mesh" rgba="0.8 0.8 0.8 1" mesh="motoman_axis_u"/>
                <body name="arm_left_link_5_r" pos="0 0.2036 0.0155" quat="0.707388 0.706825 0 0" gravcomp="0">
                  <inertial pos="-0.117624 -0.0312851 -0.00026296" quat="-0.0883248 0.705508 0.013644 0.703044" mass="0.00213955" diaginertia="8.73083e-06 8.66389e-06 3.60528e-06"/>
                  <joint name="arm_left_joint_5_r" pos="0 0 0" axis="0 0 1" range="-3.13 3.13"/>
                  <geom type="mesh" contype="0" conaffinity="0" group="1" density="0" rgba="0 0 1 1" mesh="motoman_axis_r_v"/>
                  <geom type="mesh" rgba="0 0 1 1" mesh="motoman_axis_r"/>
                  <body name="arm_left_link_6_b" pos="0 0.013 -0.155" quat="0.707388 -0.706825 0 0" gravcomp="0">
                    <inertial pos="0.0125445 0.0235749 -0.00200508" quat="0.702555 0.702555 0.0801062 0.0801062" mass="0.00182883" diaginertia="7.26798e-06 7.09e-06 2.57202e-06"/>
                    <joint name="arm_left_joint_6_b" pos="0 0 0" axis="0 0 1" range="-1.9 1.9"/>
                    <geom type="mesh" contype="0" conaffinity="0" group="1" density="0" rgba="0.8 0.8 0.8 1" mesh="motoman_axis_b_v"/>
                    <geom type="mesh" rgba="0.8 0.8 0.8 1" mesh="motoman_axis_b_remeshed"/>
                    <body name="arm_left_link_7_t" pos="0 0.144 -0.015" quat="0.707388 0.706825 0 0" gravcomp="0">
                      <joint name="arm_left_joint_7_t" pos="0 0 0" axis="0 0 1" range="-3.13 3.13"/>
                      <geom type="mesh" contype="0" conaffinity="0" group="1" density="0" rgba="0 0 1 1" mesh="motoman_axis_t_v"/>
                      <geom type="mesh" rgba="0 0 1 1" mesh="motoman_axis_t"/>
                      <geom pos="0 0 -0.035" quat="-2.1291e-08 0.00579629 -0.999983 3.67314e-06" type="mesh" contype="0" conaffinity="0" group="1" density="0" rgba="0 0 1 1" mesh="base_link_v"/>
                      <geom pos="0 0 -0.035" quat="-2.1291e-08 0.00579629 -0.999983 3.67314e-06" type="mesh" rgba="0 0 1 1" mesh="base_link"/>
                      <geom pos="8.082e-09 -6.97135e-07 -0.129901" quat="-2.1291e-08 0.00579629 -0.999983 3.67314e-06" type="mesh" contype="0" conaffinity="0" group="1" density="0" rgba="0 0 1 1" mesh="suction_cup_v"/>
                      <geom pos="8.082e-09 -6.97135e-07 -0.129901" quat="-2.1291e-08 0.00579629 -0.999983 3.67314e-06" type="mesh" rgba="0 0 1 1" mesh="suction_cup"/>
                    </body>
                  </body>
                </body>
              </body>
            </body>
          </body>
        </body>
        <body name="arm_right_link_1_s" pos="0.09996 -0.0375 0.32214" quat="0.000563312 0.000562864 -0.706825 -0.707388" gravcomp="0">
          <inertial pos="-0.198992 -0.0506283 -0.00088638" quat="0.218923 0.639794 0.30116 0.672339" mass="0.00736469" diaginertia="6.63287e-05 6.62889e-05 2.86024e-05"/>
          <joint name="arm_right_joint_1_s" pos="0 0 0" axis="0 0 1" range="-3.13 3.13"/>
          <geom type="mesh" contype="0" conaffinity="0" group="1" density="0" rgba="0 0 1 1" mesh="motoman_axis_s_v"/>
          <geom type="mesh" rgba="0 0 1 1" mesh="motoman_axis_s"/>
          <body name="arm_right_link_2_l" pos="0 0.0427 -0.2255" quat="0.707388 -0.706825 0 0" gravcomp="0">
            <inertial pos="0.00687143 0.0134517 0.00026218" quat="0.699912 0.699912 0.100612 0.100612" mass="0.00447593" diaginertia="3.37074e-05 3.068e-05 1.20626e-05"/>
            <joint name="arm_right_joint_2_l" pos="0 0 0" axis="0 0 1" range="-1.9 1.9"/>
            <geom type="mesh" contype="0" conaffinity="0" group="1" density="0" rgba="0.8 0.8 0.8 1" mesh="motoman_axis_l_v"/>
            <geom type="mesh" rgba="0.8 0.8 0.8 1" mesh="motoman_axis_l"/>
            <body name="arm_right_link_3_e" pos="0 0.179 -0.0454" quat="0.707388 0.706825 0 0" gravcomp="0">
              <inertial pos="-0.146998 0.0392846 -0.00115009" quat="0.533046 0.533046 0.46461 0.46461" mass="0.00344203" diaginertia="1.93323e-05 1.927e-05 7.94772e-06"/>
              <joint name="arm_right_joint_3_e" pos="0 0 0" axis="0 0 1" range="-2.95 2.95"/>
              <geom type="mesh" contype="0" conaffinity="0" group="1" density="0" rgba="0 0 1 1" mesh="motoman_axis_e_v"/>
              <geom type="mesh" rgba="0 0 1 1" mesh="motoman_axis_e"/>
              <body name="arm_right_link_4_u" pos="0 -0.0175 -0.181" quat="0.707388 -0.706825 0 0" gravcomp="0">
                <inertial pos="-0.0149121 0.0471967 -0.00082991" quat="0.704896 0.705064 -0.0617056 -0.0468954" mass="0.00301532" diaginertia="2.11237e-05 2.04297e-05 5.19652e-06"/>
                <joint name="arm_right_joint_4_u" pos="0 0 0" axis="0 0 -1" range="-2.36 2.36"/>
                <geom type="mesh" contype="0" conaffinity="0" group="1" density="0" rgba="0.8 0.8 0.8 1" mesh="motoman_axis_u_v"/>
                <geom type="mesh" rgba="0.8 0.8 0.8 1" mesh="motoman_axis_u"/>
                <body name="arm_right_link_5_r" pos="0 0.2036 0.0155" quat="0.707388 0.706825 0 0" gravcomp="0">
                  <inertial pos="-0.117624 -0.0312851 -0.00026296" quat="-0.0883248 0.705508 0.013644 0.703044" mass="0.00213955" diaginertia="8.73083e-06 8.66389e-06 3.60528e-06"/>
                  <joint name="arm_right_joint_5_r" pos="0 0 0" axis="0 0 -1" range="-3.13 3.13"/>
                  <geom type="mesh" contype="0" conaffinity="0" group="1" density="0" rgba="0 0 1 1" mesh="motoman_axis_r_v"/>
                  <geom type="mesh" rgba="0 0 1 1" mesh="motoman_axis_r"/>
                  <body name="arm_right_link_6_b" pos="0 0.013 -0.155" quat="0.707388 -0.706825 0 0" gravcomp="0">
                    <inertial pos="0.0125445 0.0235749 -0.00200508" quat="0.702555 0.702555 0.0801062 0.0801062" mass="0.00182883" diaginertia="7.26798e-06 7.09e-06 2.57202e-06"/>
                    <joint name="arm_right_joint_6_b" pos="0 0 0" axis="0 0 -1" range="-1.9 1.9"/>
                    <geom type="mesh" contype="0" conaffinity="0" group="1" density="0" rgba="0.8 0.8 0.8 1" mesh="motoman_axis_b_v"/>
                    <geom type="mesh" rgba="0.8 0.8 0.8 1" mesh="motoman_axis_b_remeshed"/>
                    <body name="arm_right_link_7_t" pos="0 0.144 -0.015" quat="0.707388 0.706825 0 0" gravcomp="0">
                      <joint name="arm_right_joint_7_t" pos="0 0 0" axis="0 0 -1" range="-3.13 3.13"/>
                      <geom type="mesh" contype="0" conaffinity="0" group="1" density="0" rgba="0 0 1 1" mesh="motoman_axis_t_v"/>
                      <geom type="mesh" rgba="0 0 1 1" mesh="motoman_axis_t"/>
                      <geom pos="0 0 -0.055" quat="-2.61133e-06 0.710914 -0.703279 2.58329e-06" type="mesh" contype="0" conaffinity="0" group="1" density="0" rgba="0.1 0.1 0.1 1" mesh="robotiq_arg2f_85_base_link_v"/>
                      <geom pos="0 0 -0.055" quat="-2.61133e-06 0.710914 -0.703279 2.58329e-06" type="mesh" rgba="0.1 0.1 0.1 1" mesh="robotiq_arg2f_base_link"/>
                      <geom pos="0.0305997 0.000330377 -0.109904" quat="-2.58329e-06 -0.703279 -0.710914 -2.61133e-06" type="mesh" contype="0" conaffinity="0" group="1" density="0" rgba="0.792157 0.819608 0.933333 1" mesh="robotiq_arg2f_85_outer_knuckle_v"/>
                      <geom pos="0.0305997 0.000330377 -0.109904" quat="-2.58329e-06 -0.703279 -0.710914 -2.61133e-06" type="mesh" rgba="0.792157 0.819608 0.933333 1" mesh="robotiq_arg2f_85_outer_knuckle"/>
                      <geom pos="0.0620979 0.000670455 -0.105804" quat="-2.58329e-06 -0.703279 -0.710914 -2.61133e-06" type="mesh" contype="0" conaffinity="0" group="1" density="0" rgba="0.1 0.1 0.1 1" mesh="robotiq_arg2f_85_outer_finger_v"/>
                      <geom pos="0.0620979 0.000670455 -0.105804" quat="-2.58329e-06 -0.703279 -0.710914 -2.61133e-06" type="mesh" rgba="0.1 0.1 0.1 1" mesh="robotiq_arg2f_85_outer_finger"/>
                      <geom pos="0.0681978 0.000736315 -0.152903" quat="-2.58329e-06 -0.703279 -0.710914 -2.61133e-06" type="mesh" contype="0" conaffinity="0" group="1" density="0" rgba="0.1 0.1 0.1 1" mesh="robotiq_arg2f_85_inner_finger_v"/>
                      <geom pos="0.0681978 0.000736315 -0.152903" quat="-2.58329e-06 -0.703279 -0.710914 -2.61133e-06" type="mesh" rgba="0.1 0.1 0.1 1" mesh="robotiq_arg2f_85_inner_finger"/>
                      <geom size="0.011 0.003175 0.01875" pos="0.046179 0.000498583 -0.185324" quat="-2.58329e-06 -0.703279 -0.710914 -2.61133e-06" type="box" contype="0" conaffinity="0" group="1" density="0" rgba="0.9 0.9 0.9 1"/>
                      <geom size="0.011 0.003175 0.01875" pos="0.046179 0.000498583 -0.185324" quat="-2.58329e-06 -0.703279 -0.710914 -2.61133e-06" type="box" rgba="0.9 0.9 0.9 1"/>
                      <geom pos="0.0126997 0.000137116 -0.11642" quat="-2.58329e-06 -0.703279 -0.710914 -2.61133e-06" type="mesh" contype="0" conaffinity="0" group="1" density="0" rgba="0.1 0.1 0.1 1" mesh="robotiq_arg2f_85_inner_knuckle_v"/>
                      <geom pos="0.0126997 0.000137116 -0.11642" quat="-2.58329e-06 -0.703279 -0.710914 -2.61133e-06" type="mesh" rgba="0.1 0.1 0.1 1" mesh="robotiq_arg2f_85_inner_knuckle"/>
                      <geom pos="-0.0305989 -0.000330369 -0.109904" quat="-2.61133e-06 0.710914 -0.703279 2.58329e-06" type="mesh" contype="0" conaffinity="0" group="1" density="0" rgba="0.792157 0.819608 0.933333 1" mesh="robotiq_arg2f_85_outer_knuckle_v"/>
                      <geom pos="-0.0305989 -0.000330369 -0.109904" quat="-2.61133e-06 0.710914 -0.703279 2.58329e-06" type="mesh" rgba="0.792157 0.819608 0.933333 1" mesh="robotiq_arg2f_85_outer_knuckle"/>
                      <geom pos="-0.0620971 -0.000670447 -0.105804" quat="-2.61133e-06 0.710914 -0.703279 2.58329e-06" type="mesh" contype="0" conaffinity="0" group="1" density="0" rgba="0.1 0.1 0.1 1" mesh="robotiq_arg2f_85_outer_finger_v"/>
                      <geom pos="-0.0620971 -0.000670447 -0.105804" quat="-2.61133e-06 0.710914 -0.703279 2.58329e-06" type="mesh" rgba="0.1 0.1 0.1 1" mesh="robotiq_arg2f_85_outer_finger"/>
                      <geom pos="-0.0681964 -0.000736299 -0.152905" quat="-2.61133e-06 0.710914 -0.703279 2.58329e-06" type="mesh" contype="0" conaffinity="0" group="1" density="0" rgba="0.1 0.1 0.1 1" mesh="robotiq_arg2f_85_inner_finger_v"/>
                      <geom pos="-0.0681964 -0.000736299 -0.152905" quat="-2.61133e-06 0.710914 -0.703279 2.58329e-06" type="mesh" rgba="0.1 0.1 0.1 1" mesh="robotiq_arg2f_85_inner_finger"/>
                      <geom size="0.011 0.003175 0.01875" pos="-0.0461771 -0.000498563 -0.185324" quat="-2.61133e-06 0.710914 -0.703279 2.58329e-06" type="box" contype="0" conaffinity="0" group="1" density="0" rgba="0.9 0.9 0.9 1"/>
                      <geom size="0.011 0.003175 0.01875" pos="-0.0461771 -0.000498563 -0.185324" quat="-2.61133e-06 0.710914 -0.703279 2.58329e-06" type="box" rgba="0.9 0.9 0.9 1"/>
                      <geom pos="-0.0126988 -0.000137106 -0.11642" quat="-2.61133e-06 0.710914 -0.703279 2.58329e-06" type="mesh" contype="0" conaffinity="0" group="1" density="0" rgba="0.1 0.1 0.1 1" mesh="robotiq_arg2f_85_inner_knuckle_v"/>
                      <geom pos="-0.0126988 -0.000137106 -0.11642" quat="-2.61133e-06 0.710914 -0.703279 2.58329e-06" type="mesh" rgba="0.1 0.1 0.1 1" mesh="robotiq_arg2f_85_inner_knuckle"/>
                    </body>
                  </body>
                </body>
              </body>
            </body>
          </body>
        </body>
      </body>
    </body>
  </worldbody>
  <actuator>
    <position name="torso_b1" joint="torso_joint_b1" kp="5000"/>
    <position name="arm_left_1_s" joint="arm_left_joint_1_s" kp="500"/>
    <position name="arm_left_2_l" joint="arm_left_joint_2_l" kp="500"/>
    <position name="arm_left_3_e" joint="arm_left_joint_3_e" kp="500"/>
    <position name="arm_left_4_u" joint="arm_left_joint_4_u" kp="500"/>
    <position name="arm_left_5_r" joint="arm_left_joint_5_r" kp="500"/>
    <position name="arm_left_6_b" joint="arm_left_joint_6_b" kp="500"/>
    <position name="arm_left_7_t" joint="arm_left_joint_7_t" kp="500"/>
    <position name="arm_right_1_s" joint="arm_right_joint_1_s" kp="500"/>
    <position name="arm_right_2_l" joint="arm_right_joint_2_l" kp="500"/>
    <position name="arm_right_3_e" joint="arm_right_joint_3_e" kp="500"/>
    <position name="arm_right_4_u" joint="arm_right_joint_4_u" kp="500"/>
    <position name="arm_right_5_r" joint="arm_right_joint_5_r" kp="500"/>
    <position name="arm_right_6_b" joint="arm_right_joint_6_b" kp="500"/>
    <position name="arm_right_7_t" joint="arm_right_joint_7_t" kp="500"/>
  </actuator>
</mujoco>
