<?xml version="1.0" ?>
<!-- =================================================================================== -->
<!-- |    This document was autogenerated by xacro from sda10f_uni_kin_ref_kin_macro_newKin.xacro | -->
<!-- |    EDITING THIS FILE BY HAND IS NOT RECOMMENDED                                 | -->
<!-- =================================================================================== -->
<robot name="sda10f" xmlns:xacro="http://ros.org/wiki/xacro">
  <!-- link list -->
	<mujoco> <compiler meshdir="meshes" balanceinertia="true" discardvisual="false"/> </mujoco>

  <link name="base">
  </link>

  <joint name="base_joint" type="fixed">
    <parent link="base"/>
    <child link="base_link"/>
  </joint>

  <link name="base_link">
    <visual>
      <geometry>
        <mesh filename="motoman_base_v.stl"/>
      </geometry>
      <material name="blue">
        <color rgba="0 0 1 1"/>
      </material>
    </visual>
    <collision>
      <geometry>
        <mesh filename="motoman_base.stl"/>
      </geometry>
      <material name="yellow">
        <color rgba="0 1 1 1"/>
      </material>
    </collision>
    <inertial>
    <origin xyz="0.59411730 0.00220938 0.06245062"/>
    <mass value="0.11690470"/>
    <inertia ixx="0.00301106" ixy="-0.00000002" ixz="-0.00069198" iyy="0.00812166" iyz="0.00000006" izz="0.00804492"/>
    </inertial>
  </link>

  <!-- joint list -->
  <!-- <joint name="torso_joint_b1" type="revolute"> -->
  <joint name="torso_joint_b1" type="revolute">
    <parent link="base_link"/>
    <child link="torso_link_b1"/>
    <origin rpy="0 0 0" xyz="0.09257 0 0.877"/>
    <axis xyz="0 0 1"/>
    <limit effort="100" lower="-1.58" upper="1.58" velocity="2.26"/>
    <!-- <limit effort="100" lower="-2.9570" upper="2.9570" velocity="2.26"/> -->
    <!-- <limit effort="100" lower="-0.0001" upper="0.0001" velocity="2.26"/> -->
  </joint>
  <!-- end of joint list -->

  <link name="torso_link_b1">
    <visual>
      <origin rpy="0 0 0" xyz="0 0 0"/>
      <geometry>
        <mesh filename="motoman_axis_b1_v.stl"/>
      </geometry>
      <material name="silver">
        <color rgba="0.8 0.8 0.8 1"/>
      </material>
    </visual>
    <collision>
      <origin rpy="0 0 0" xyz="0 0 0"/>
      <geometry>
        <mesh filename="motoman_axis_b1_remeshed.stl"/>
        <!-- <mesh filename="sda10f_description/meshes/sda10f/collision/motoman_axis_b1.stl"/> -->
      </geometry>
      <material name="yellow"/>
    </collision>
    <inertial>
    <origin xyz="0.29769593 -0.00048507 0.07556016"/>
    <mass value="0.02557033"/>
    <inertia ixx="0.00027808" ixy="-0.00000000" ixz="-0.00009991" iyy="0.00050765" iyz="0.00000000" izz="0.00047731"/>
    </inertial>
  </link>

  <link name="arm_left_link_1_s">
    <visual>
      <origin rpy="0 0 0" xyz="0 0 0"/>
      <geometry>
        <mesh filename="motoman_axis_s_v.stl"/>
        <!-- <mesh filename="sda10f_description/meshes/sda10f/visual/motoman_axis_s.stl"/> -->
      </geometry>
      <material name="blue"/>
      <!-- <material name="blue">
        <color rgba="0.65 0.65 0.65 1"/>
      </material> -->
    </visual>
    <collision>
      <origin rpy="0 0 0" xyz="0 0 0"/>
      <geometry>
        <mesh filename="motoman_axis_s.stl"/>
        <!-- <mesh filename="sda10f_description/meshes/sda10f/collision/motoman_axis_s.stl"/> -->
      </geometry>
      <material name="yellow"/>
    </collision>
    <inertial>
    <origin xyz="-0.19899234 -0.05062831 -0.00088638"/>
    <mass value="0.00736469"/>
    <inertia ixx="0.00002919" ixy="-0.00000467" ixz="-0.00000000" iyy="0.00006572" iyz="0.00000002" izz="0.00006631"/>
    </inertial>
  </link>
  <link name="arm_left_link_2_l">
    <visual>
      <origin rpy="0 0 0" xyz="0 0 0"/>
      <geometry>
        <mesh filename="motoman_axis_l_v.stl"/>
        <!-- <mesh filename="sda10f_description/meshes/sda10f/visual/motoman_axis_l.stl"/> -->
      </geometry>
      <material name="silver"/>
    </visual>
    <collision>
      <origin rpy="0 0 0" xyz="0 0 0"/>
      <geometry>
        <mesh filename="motoman_axis_l.stl"/>
        <!-- <mesh filename="sda10f_description/meshes/sda10f/collision/motoman_axis_l.stl"/> -->
      </geometry>
      <material name="yellow"/>
    </collision>
    <inertial>
    <origin xyz="0.00687143 0.01345170 0.00026218"/>
    <mass value="0.00447593"/>
    <inertia ixx="0.00003199" ixy="0.00000585" ixz="-0.00000000" iyy="0.00001378" iyz="0.00000000" izz="0.00003068"/>
    </inertial>
  </link>
  <link name="arm_left_link_3_e">
    <visual>
      <origin rpy="0 0 0" xyz="0 0 0"/>
      <geometry>
        <mesh filename="motoman_axis_e_v.stl"/>
        <!-- <mesh filename="sda10f_description/meshes/sda10f/visual/motoman_axis_e.stl"/> -->
      </geometry>
      <material name="blue"/>
    </visual>
    <collision>
      <origin rpy="0 0 0" xyz="0 0 0"/>
      <geometry>
        <mesh filename="motoman_axis_e.stl"/>
        <!-- <mesh filename="sda10f_description/meshes/sda10f/collision/motoman_axis_e.stl"/> -->
      </geometry>
      <material name="yellow"/>
    </collision>
    <inertial>
    <origin xyz="-0.14699799 0.03928457 -0.00115009"/>
    <mass value="0.00344203"/>
    <inertia ixx="0.00000816" ixy="0.00000154" ixz="-0.00000000" iyy="0.00001912" iyz="0.00000000" izz="0.00001927"/>
    </inertial>
  </link>
  <link name="arm_left_link_4_u">
    <visual>
      <origin rpy="0 0 0" xyz="0 0 0"/>
      <geometry>
        <mesh filename="motoman_axis_u_v.stl"/>
        <!-- <mesh filename="sda10f_description/meshes/sda10f/visual/motoman_axis_u.stl"/> -->
      </geometry>
      <material name="silver"/>
    </visual>
    <collision>
      <origin rpy="0 0 0" xyz="0 0 0"/>
      <geometry>
        <mesh filename="motoman_axis_u.stl"/>
        <!-- <mesh filename="sda10f_description/meshes/sda10f/collision/motoman_axis_u.stl"/> -->
      </geometry>
      <material name="yellow"/>
    </collision>
    <inertial>
    <origin xyz="-0.01491214 0.04719666 -0.00082991"/>
    <mass value="0.00301532"/>
    <inertia ixx="0.00002075" ixy="-0.00000241" ixz="0.00000001" iyy="0.00000557" iyz="-0.00000003" izz="0.00002043"/>
    </inertial>
  </link>
  <link name="arm_left_link_5_r">
    <visual>
      <origin rpy="0 0 0" xyz="0 0 0"/>
      <geometry>
        <mesh filename="motoman_axis_r_v.stl"/>
        <!-- <mesh filename="sda10f_description/meshes/sda10f/visual/motoman_axis_r.stl"/> -->
      </geometry>
      <material name="blue"/>
    </visual>
    <collision>
      <origin rpy="0 0 0" xyz="0 0 0"/>
      <geometry>
        <mesh filename="motoman_axis_r.stl"/>
        <!-- <mesh filename="sda10f_description/meshes/sda10f/collision/motoman_axis_r.stl"/> -->
      </geometry>
      <material name="yellow"/>
    </collision>
    <inertial>
    <origin xyz="-0.11762401 -0.03128507 -0.00026296"/>
    <mass value="0.00213955"/>
    <inertia ixx="0.00000371" ixy="-0.00000072" ixz="-0.00000002" iyy="0.00000856" iyz="-0.00000001" izz="0.00000873"/>
    </inertial>
  </link>
  <link name="arm_left_link_6_b">
    <visual>
      <origin rpy="0 0 0" xyz="0 0 0"/>
      <geometry>
        <mesh filename="motoman_axis_b_v.stl"/>
        <!-- <mesh filename="sda10f_description/meshes/sda10f/visual/motoman_axis_b.stl"/> -->
      </geometry>
      <material name="silver"/>
    </visual>
    <collision>
      <origin rpy="0 0 0" xyz="0 0 0"/>
      <geometry>
        <mesh filename="motoman_axis_b_remeshed.stl"/>
        <!-- <mesh filename="sda10f_description/meshes/sda10f/collision/motoman_axis_b.stl"/> -->
      </geometry>
      <material name="yellow"/>
    </collision>
    <inertial>
    <origin xyz="0.01254451 0.02357485 -0.00200508"/>
    <mass value="0.00182883"/>
    <inertia ixx="0.00000703" ixy="0.00000103" ixz="0.00000000" iyy="0.00000281" iyz="-0.00000000" izz="0.00000709"/>
    </inertial>
  </link>
  <link name="arm_left_link_7_t">
    <visual>
      <geometry>
        <mesh filename="motoman_axis_t_v.stl"/>
        <!-- <mesh filename="sda10f_description/meshes/sda10f/visual/motoman_axis_t.stl"/> -->
      </geometry>
      <material name="blue"/>
    </visual>
    <collision>
      <geometry>
        <mesh filename="motoman_axis_t.stl"/>
        <!-- <mesh filename="sda10f_description/meshes/sda10f/collision/motoman_axis_t.stl"/> -->
      </geometry>
      <material name="yellow"/>
    </collision>
  </link>
  <link name="arm_left_link_tool0"/>

  <joint name="arm_left_joint_1_s" type="revolute">
    <parent link="torso_link_b1"/>
    <child link="arm_left_link_1_s"/>
     <origin rpy="1.57 0 0.0" xyz="0.09996 0.0375 0.32214"/>
    <axis xyz="0 0 -1.0"/>
    <limit effort="0" lower="-3.13" upper="3.13" velocity="2.95"/>
    <!-- <dynamics damping="3.5"/> -->
  </joint>
  <joint name="arm_left_joint_2_l" type="revolute">
    <parent link="arm_left_link_1_s"/>
    <child link="arm_left_link_2_l"/>
    <origin rpy="-1.57 0 0" xyz="0 0.0427 -0.2255"/>
    <axis xyz="0 0 -1.0"/>
    <limit effort="0" lower="-1.90" upper="1.90" velocity="2.95"/>
    <!-- <dynamics damping="3.5"/> -->
  </joint>
  <joint name="arm_left_joint_3_e" type="revolute">
    <parent link="arm_left_link_2_l"/>
    <child link="arm_left_link_3_e"/>
    <origin rpy="1.57 0 0" xyz="0 0.1790 -0.0454"/>
    <axis xyz="0 0 -1.0"/>
    <limit effort="0" lower="-2.95" upper="2.95" velocity="2.95"/>
    <!-- <dynamics damping="3.5"/> -->
  </joint>
  <joint name="arm_left_joint_4_u" type="revolute">
    <parent link="arm_left_link_3_e"/>
    <child link="arm_left_link_4_u"/>
    <origin rpy="-1.57 0 0" xyz="0 -0.0175 -0.181"/>
    <axis xyz="0 0 1"/>
    <limit effort="0" lower="-2.36" upper="2.36" velocity="2.95"/>
    <!-- <dynamics damping="3.5"/> -->
  </joint>
  <joint name="arm_left_joint_5_r" type="revolute">
    <parent link="arm_left_link_4_u"/>
    <child link="arm_left_link_5_r"/>
    <origin rpy="1.57 0 0" xyz="0 0.2036 0.0155"/>
    <axis xyz="0 0 1"/>
    <limit effort="0" lower="-3.13" upper="3.13" velocity="3.48"/>
    <!-- <dynamics damping="3.5"/> -->
  </joint>
  <joint name="arm_left_joint_6_b" type="revolute">
    <parent link="arm_left_link_5_r"/>
    <child link="arm_left_link_6_b"/>
    <origin rpy="-1.57 0 0" xyz="0 0.0130 -0.155"/>
    <axis xyz="0 0 1"/>
    <limit effort="0" lower="-1.90" upper="1.90" velocity="3.48"/>
    <!-- <dynamics damping="3.5"/> -->
  </joint>
  <joint name="arm_left_joint_7_t" type="revolute">
    <parent link="arm_left_link_6_b"/>
    <child link="arm_left_link_7_t"/>
     <origin rpy="1.57 0 0" xyz="0 0.144 -0.015"/>
    <axis xyz="0 0 1"/>
    <limit effort="0" lower="-3.13" upper="3.13" velocity="6.97"/>
    <!-- <dynamics damping="3.5"/> -->
  </joint>
  <joint name="arm_left_joint_tool0" type="fixed">
    <!-- the following line is modified by Rui-->
    <!-- <origin rpy="0 0 -3.13" xyz="0 0 -0.09"/> -->
    <origin rpy="0 0 -3.13" xyz="0 0 -0.035"/>
    <!-- <origin rpy="0 0 -3.13" xyz="0 0 -0.07"/> -->
    <!-- <origin rpy="0 0 -3.13" xyz="0 0 -0.025"/> -->
    <!-- <origin rpy="0 0 -3.13" xyz="0 0 -0.0325"/> -->
    <!-- <origin rpy="0 0 -3.13" xyz="0 0 0.0"/> -->
    <parent link="arm_left_link_7_t"/>
    <child link="arm_left_link_tool0"/>
    <!-- <dynamics damping="3.5"/> -->
  </joint>
  <!-- end of joint list -->
  <link name="arm_right_link_1_s">
    <visual>
      <origin rpy="0 0 0" xyz="0 0 0"/>
      <geometry>
        <mesh filename="motoman_axis_s_v.stl"/>
        <!-- <mesh filename="sda10f_description/meshes/sda10f/visual/motoman_axis_s.stl"/> -->
      </geometry>
      <material name="blue">
        <!-- <color rgba="0.65 0.65 0.65 1"/> -->
      </material>
    </visual>
    <collision>
      <origin rpy="0 0 0" xyz="0 0 0"/>
      <geometry>
        <mesh filename="motoman_axis_s.stl"/>
        <!-- <mesh filename="sda10f_description/meshes/sda10f/collision/motoman_axis_s.stl"/> -->
      </geometry>
      <material name="yellow"/>
    </collision>
    <inertial>
    <origin xyz="-0.19899234 -0.05062831 -0.00088638"/>
    <mass value="0.00736469"/>
    <inertia ixx="0.00002919" ixy="-0.00000467" ixz="-0.00000000" iyy="0.00006572" iyz="0.00000002" izz="0.00006631"/>
    </inertial>
  </link>
  <link name="arm_right_link_2_l">
    <visual>
      <origin rpy="0 0 0" xyz="0 0 0"/>
      <geometry>
        <mesh filename="motoman_axis_l_v.stl"/>
        <!-- <mesh filename="sda10f_description/meshes/sda10f/visual/motoman_axis_l.stl"/> -->
      </geometry>
      <material name="silver"/>
    </visual>
    <collision>
      <origin rpy="0 0 0" xyz="0 0 0"/>
      <geometry>
        <mesh filename="motoman_axis_l.stl"/>
        <!-- <mesh filename="sda10f_description/meshes/sda10f/collision/motoman_axis_l.stl"/> -->
      </geometry>
      <material name="yellow"/>
    </collision>
    <inertial>
    <origin xyz="0.00687143 0.01345170 0.00026218"/>
    <mass value="0.00447593"/>
    <inertia ixx="0.00003199" ixy="0.00000585" ixz="-0.00000000" iyy="0.00001378" iyz="0.00000000" izz="0.00003068"/>
    </inertial>
  </link>
  <link name="arm_right_link_3_e">
    <visual>
      <origin rpy="0 0 0" xyz="0 0 0"/>
      <geometry>
        <mesh filename="motoman_axis_e_v.stl"/>
        <!-- <mesh filename="sda10f_description/meshes/sda10f/visual/motoman_axis_e.stl"/> -->
      </geometry>
      <material name="blue"/>
    </visual>
    <collision>
      <origin rpy="0 0 0" xyz="0 0 0"/>
      <geometry>
        <mesh filename="motoman_axis_e.stl"/>
        <!-- <mesh filename="sda10f_description/meshes/sda10f/collision/motoman_axis_e.stl"/> -->
      </geometry>
      <material name="yellow"/>
    </collision>
    <inertial>
    <origin xyz="-0.14699799 0.03928457 -0.00115009"/>
    <mass value="0.00344203"/>
    <inertia ixx="0.00000816" ixy="0.00000154" ixz="-0.00000000" iyy="0.00001912" iyz="0.00000000" izz="0.00001927"/>
    </inertial>
  </link>
  <link name="arm_right_link_4_u">
    <visual>
      <origin rpy="0 0 0" xyz="0 0 0"/>
      <geometry>
        <mesh filename="motoman_axis_u_v.stl"/>
        <!-- <mesh filename="sda10f_description/meshes/sda10f/visual/motoman_axis_u.stl"/> -->
      </geometry>
      <material name="silver"/>
    </visual>
    <collision>
      <origin rpy="0 0 0" xyz="0 0 0"/>
      <geometry>
        <mesh filename="motoman_axis_u.stl"/>
        <!-- <mesh filename="sda10f_description/meshes/sda10f/collision/motoman_axis_u.stl"/> -->
      </geometry>
      <material name="yellow"/>
    </collision>
    <inertial>
    <origin xyz="-0.01491214 0.04719666 -0.00082991"/>
    <mass value="0.00301532"/>
    <inertia ixx="0.00002075" ixy="-0.00000241" ixz="0.00000001" iyy="0.00000557" iyz="-0.00000003" izz="0.00002043"/>
    </inertial>
  </link>
  <link name="arm_right_link_5_r">
    <visual>
      <origin rpy="0 0 0" xyz="0 0 0"/>
      <geometry>
        <mesh filename="motoman_axis_r_v.stl"/>
        <!-- <mesh filename="sda10f_description/meshes/sda10f/visual/motoman_axis_r.stl"/> -->
      </geometry>
      <material name="blue"/>
    </visual>
    <collision>
      <origin rpy="0 0 0" xyz="0 0 0"/>
      <geometry>
        <mesh filename="motoman_axis_r.stl"/>
        <!-- <mesh filename="sda10f_description/meshes/sda10f/collision/motoman_axis_r.stl"/> -->
      </geometry>
      <material name="yellow"/>
    </collision>
    <inertial>
    <origin xyz="-0.11762401 -0.03128507 -0.00026296"/>
    <mass value="0.00213955"/>
    <inertia ixx="0.00000371" ixy="-0.00000072" ixz="-0.00000002" iyy="0.00000856" iyz="-0.00000001" izz="0.00000873"/>
    </inertial>
  </link>
  <link name="arm_right_link_6_b">
    <visual>
      <origin rpy="0 0 0" xyz="0 0 0"/>
      <geometry>
        <mesh filename="motoman_axis_b_v.stl"/>
        <!-- <mesh filename="sda10f_description/meshes/sda10f/visual/motoman_axis_b.stl"/> -->
      </geometry>
      <material name="silver"/>
    </visual>
    <collision>
      <origin rpy="0 0 0" xyz="0 0 0"/>
      <geometry>
        <mesh filename="motoman_axis_b_remeshed.stl"/>
        <!-- <mesh filename="sda10f_description/meshes/sda10f/collision/motoman_axis_b.stl"/> -->
      </geometry>
      <material name="yellow"/>
    </collision>
    <inertial>
    <origin xyz="0.01254451 0.02357485 -0.00200508"/>
    <mass value="0.00182883"/>
    <inertia ixx="0.00000703" ixy="0.00000103" ixz="0.00000000" iyy="0.00000281" iyz="-0.00000000" izz="0.00000709"/>
    </inertial>
  </link>
  <link name="arm_right_link_7_t">
    <visual>
      <geometry>
        <mesh filename="motoman_axis_t_v.stl"/>
        <!-- <mesh filename="sda10f_description/meshes/sda10f/visual/motoman_axis_t.stl"/> -->
      </geometry>
      <material name="blue"/>
    </visual>
    <collision>
      <geometry>
        <mesh filename="motoman_axis_t.stl"/>
        <!-- <mesh filename="sda10f_description/meshes/sda10f/collision/motoman_axis_t.stl"/> -->
      </geometry>
      <material name="yellow"/>
    </collision>
  </link>
  <link name="arm_right_link_tool0"/>

  <joint name="arm_right_joint_1_s" type="revolute">
    <parent link="torso_link_b1"/>
    <child link="arm_right_link_1_s"/>
    <origin rpy="1.57 0 -3.14" xyz="0.09996 -0.0375 0.32214"/>
    <axis xyz="0 0 1.0"/>
    <limit effort="0" lower="-3.13" upper="3.13" velocity="2.95"/>
  </joint>
  <joint name="arm_right_joint_2_l" type="revolute">
    <parent link="arm_right_link_1_s"/>
    <child link="arm_right_link_2_l"/>
    <origin rpy="-1.57 0 0" xyz="0 0.0427 -0.2255"/>
    <axis xyz="0 0 1.0"/>
    <limit effort="0" lower="-1.90" upper="1.90" velocity="2.95"/>
  </joint>
  <joint name="arm_right_joint_3_e" type="revolute">
    <parent link="arm_right_link_2_l"/>
    <child link="arm_right_link_3_e"/>
    <origin rpy="1.57 0 0" xyz="0 0.1790 -0.0454"/>
    <axis xyz="0 0 1.0"/>
    <limit effort="0" lower="-2.95" upper="2.95" velocity="2.95"/>
  </joint>
  <joint name="arm_right_joint_4_u" type="revolute">
    <parent link="arm_right_link_3_e"/>
    <child link="arm_right_link_4_u"/>
    <origin rpy="-1.57 0 0" xyz="0 -0.0175 -0.181"/>
    <axis xyz="0 0 -1"/>
    <limit effort="0" lower="-2.36" upper="2.36" velocity="2.95"/>
  </joint>
  <joint name="arm_right_joint_5_r" type="revolute">
    <parent link="arm_right_link_4_u"/>
    <child link="arm_right_link_5_r"/>
    <origin rpy="1.57 0 0" xyz="0 0.2036 0.0155"/>
    <axis xyz="0 0 -1"/>
    <limit effort="0" lower="-3.13" upper="3.13" velocity="3.48"/>
  </joint>
  <joint name="arm_right_joint_6_b" type="revolute">
    <parent link="arm_right_link_5_r"/>
    <child link="arm_right_link_6_b"/>
    <origin rpy="-1.57 0 0" xyz="0 0.0130 -0.155"/>
    <axis xyz="0 0 -1"/>
    <limit effort="0" lower="-1.90" upper="1.90" velocity="3.48"/>
  </joint>
  <joint name="arm_right_joint_7_t" type="revolute">
    <parent link="arm_right_link_6_b"/>
    <child link="arm_right_link_7_t"/>
    <origin rpy="1.57 0 0" xyz="0 0.144 -0.015"/>
    <axis xyz="0 0 -1"/>
    <limit effort="0" lower="-3.13" upper="3.13" velocity="6.97"/>
  </joint>
  <joint name="arm_right_joint_tool0" type="fixed">
    <!-- the following line is modified by Rui-->
    <!-- <origin rpy="0 0 -3.13" xyz="0 0 -0.025"/> -->
    <!-- the following line is modified by Yinglong-->
    <origin rpy="0 0 -3.13" xyz="0 0 -0.055"/>    
    <!-- <origin rpy="0 0 -3.13" xyz="0 0 -0.0325"/> -->
    <!-- <origin rpy="0 0 -3.13" xyz="0 0 0.0"/> origin -->
    <parent link="arm_right_link_7_t"/>
    <child link="arm_right_link_tool0"/>
  </joint>
  <!-- Links -->

  <joint name="motoman_left_joint_pre_ee" type="fixed">
    <parent link="arm_left_link_tool0"/>
    <child link="onrobot_vgc10_base_link"/>
    <origin rpy="3.1416 0 0" xyz="0 0 0.0"/>
    <!-- <origin rpy="3.141 0 0" xyz="0 0 -0.07"/> -->
    <!-- <origin rpy="3.141 0 0" xyz="0 0 -0.028"/> -->
  </joint>


    <link name="onrobot_vgc10_base_link">
      <!-- <inertial> -->
      <!--   <origin xyz="0.0 0.0 0.0" rpy="0 0 0" /> -->
      <!--   <mass value="0.6" /> -->
      <!--   <inertia ixx="1.0E-03" ixy="1.0E-06" ixz="1.0E-06" iyy="1.0E-03" iyz="1.0E-06" izz="1.0E-03" /> -->
      <!-- </inertial> -->
      <visual>
        <origin xyz="0 0 0" rpy="0 0 0" />
        <geometry>
          <mesh filename="base_link_v.stl" />
        </geometry>
        <material name="blue">
          <color rgba="0 0 1 1" />
        </material>        
      </visual>
      <collision>
        <origin xyz="0 0 0" rpy="0 0 0" />
        <geometry>
          <mesh filename="base_link.stl" />
        </geometry>
      </collision>
    <inertial>
    <origin xyz="0.04835756 -0.00001145 -0.00005143"/>
    <mass value="0.00081386"/>
    <inertia ixx="0.00000110" ixy="0.00000000" ixz="0.00000000" iyy="0.00000115" iyz="-0.00000000" izz="0.00000115"/>
    </inertial>      
    </link>

    <link name="onrobot_vgc10_suction">
      <!-- <inertial> -->
      <!--   <origin xyz="0.0 0.0 0.0" rpy="0 0 0" /> -->
      <!--   <mass value="0.2" /> -->
      <!--   <inertia ixx="1.0E-03" ixy="1.0E-06" ixz="1.0E-06" iyy="1.0E-03" iyz="1.0E-06" izz="1.0E-03" /> -->
      <!-- </inertial> -->
      <visual>
        <origin xyz="0 0 0" rpy="0 0 0" />
        <geometry>
          <mesh filename="suction_cup_v.stl" />
        </geometry>
        <material name="blue">
          <color rgba="0 0 1 1" />
        </material>        
      </visual>
      <collision>
        <origin xyz="0 0 0" rpy="0 0 0" />
        <geometry>
          <mesh filename="suction_cup.stl" />
        </geometry>
      </collision>
    <inertial>
    <origin xyz="0.05012417 -0.00023699 -0.00003326"/>
    <mass value="0.00005331"/>
    <inertia ixx="0.00000001" ixy="0.00000000" ixz="0.00000000" iyy="0.00000003" iyz="-0.00000000" izz="0.00000003"/>
    </inertial>
    </link>
    <joint name="onrobot_vgc10_suction_joint" type="fixed">
      <origin xyz="0 0 0.094901" rpy="0 0 0" />
      <parent link="onrobot_vgc10_base_link" />
      <child link="onrobot_vgc10_suction" />
      <axis xyz="1 0 0" />
    </joint>

  <joint name="motoman_left_joint_ee" type="fixed">
    <parent link="onrobot_vgc10_base_link"/>
    <child link="motoman_left_ee"/>
    <origin rpy="0 0 0" xyz="0 0 0.18"/>
    <!-- <origin rpy="0 0 0" xyz="0 0 0.3015"/> -->
    <!-- <origin rpy="0 0 0" xyz="0 0 0.068"/> -->
    <!-- <origin rpy="0 0 0" xyz="0 0 0"/> -->
  </joint>
  <link name="motoman_left_ee">
    </link>

  <joint name="motoman_right_joint_pre_ee" type="fixed">
    <parent link="arm_right_link_tool0"/>
    <!-- <child link="motoman_right_hand"/> -->
    <child link="robotiq_arg2f_base_link"/>
    <origin rpy="3.1416 0 1.57" xyz="0 0 0.0"/>
    <!-- <origin rpy="3.1416 0 0" xyz="0 0 0.0"/> -->
    <!-- <origin rpy="3.141 0 0" xyz="0 0 -0.035"/> -->
  </joint>

  <!-- <link name="motoman_right_hand">
    <visual>
      <geometry>
        <mesh filename="modelO42.stl"/>
      </geometry>
      <material name="blue">
        <color rgba="0 0 1 1"/>
      </material>
    </visual>
    <collision>
      <geometry>
        <mesh filename="modelO42.stl"/>
      </geometry>
      <material name="yellow">
        <color rgba="0 1 1 1"/>
      </material>
    </collision>
  </link> -->

  <joint name="motoman_right_joint_ee" type="fixed">
    <parent link="robotiq_arg2f_base_link"/>
    <!-- <parent link="motoman_right_hand"/> -->
    <child link="motoman_right_ee"/>
    <origin rpy="0 0 0" xyz="0 0 0.135"/>
  </joint>
  <link name="motoman_right_ee"></link>


  <link name="robotiq_arg2f_base_link">
    <!-- <inertial>
      <origin rpy="0 0 0" xyz="8.625E-08 -4.6583E-06 0.03145"/>
      <mass value="0.22652"/>
      <inertia ixx="0.00020005" ixy="-4.2442E-10" ixz="-2.9069E-10" iyy="0.00017832" iyz="-3.4402E-08" izz="0.00013478"/>
    </inertial> -->
    <visual>
      <origin rpy="0 0 0" xyz="0 0 0"/>
      <geometry>
        <mesh filename="robotiq_arg2f_85_base_link_v.stl" scale="0.001 0.001 0.001"/>
      </geometry>
      <material name="">
        <color rgba="0.1 0.1 0.1 1"/>
      </material>
    </visual>
    <collision>
      <origin rpy="0 0 0" xyz="0 0 0"/>
      <geometry>
        <mesh filename="robotiq_arg2f_base_link.stl"/>
      </geometry>
    </collision>
    <inertial>
    <origin xyz="0.04288860 -0.00153989 0.00016929"/>
    <mass value="0.00031045"/>
    <inertia ixx="0.00000020" ixy="-0.00000000" ixz="0.00000000" iyy="0.00000024" iyz="0.00000000" izz="0.00000028"/>
    </inertial>
  </link>
  <link name="left_outer_knuckle">
    <!--<inertial>
        <origin xyz="-0.000200000000003065 0.0199435877845359 0.0292245259211331" rpy="0 0 0" />
        <mass value="0.00853198276973456" />
        <inertia ixx="2.89328108496468E-06" ixy="-1.57935047237397E-19" ixz="-1.93980378593255E-19" iyy="1.86719750325683E-06" iyz="-1.21858577871576E-06" izz="1.21905238907251E-06" />
        </inertial> -->
    <visual>
      <origin rpy="0 0 0" xyz="0 0 0"/>
      <geometry>
        <mesh filename="robotiq_arg2f_85_outer_knuckle_v.stl" scale="0.001 0.001 0.001"/>
      </geometry>
      <material name="">
        <color rgba="0.792156862745098 0.819607843137255 0.933333333333333 1"/>
      </material>
    </visual>
    <collision>
      <origin rpy="0 0 0" xyz="0 0 0"/>
      <geometry>
        <mesh filename="robotiq_arg2f_85_outer_knuckle.stl" scale="0.001 0.001 0.001"/>
      </geometry>
    </collision>
    <inertial>
    <origin xyz="0.00000000 0.01959428 0.00167623"/>
    <mass value="0.00001294"/>
    <inertia ixx="0.00000000" ixy="0.00000000" ixz="0.00000000" iyy="0.00000000" iyz="-0.00000000" izz="0.00000000"/>
    </inertial>
  </link>
  <link name="left_outer_finger">
    <!--<inertial>
        <origin xyz="0.00030115855001899 0.0373907951953854 -0.0208027427000385" rpy="0 0 0" />
        <mass value="0.022614240507152" />
        <inertia ixx="1.52518312458174E-05" ixy="9.76583423954399E-10" ixz="-5.43838577022588E-10" iyy="6.17694243867776E-06" iyz="6.78636130740228E-06" izz="1.16494917907219E-05" />
        </inertial> -->
    <visual>
      <origin rpy="0 0 0" xyz="0 0 0"/>
      <geometry>
        <mesh filename="robotiq_arg2f_85_outer_finger_v.stl" scale="0.001 0.001 0.001"/>
      </geometry>
      <material name="">
        <color rgba="0.1 0.1 0.1 1"/>
      </material>
    </visual>
    <collision>
      <origin rpy="0 0 0" xyz="0 0 0"/>
      <geometry>
        <mesh filename="robotiq_arg2f_85_outer_finger.stl" scale="0.001 0.001 0.001"/>
      </geometry>
    </collision>
    <inertial>
    <origin xyz="0.00000000 0.00303447 0.02345961"/>
    <mass value="0.00001778"/>
    <inertia ixx="0.00000001" ixy="-0.00000000" ixz="-0.00000000" iyy="0.00000001" iyz="-0.00000000" izz="0.00000000"/>
    </inertial>
  </link>
  <link name="left_inner_finger">
    <!--<inertial>
        <origin xyz="0.000299999999999317 0.0160078233491243 -0.0136945669206257" rpy="0 0 0" />
        <mass value="0.0104003125914103" />
        <inertia ixx="2.71909453810972E-06" ixy="1.35402465472579E-21" ixz="-7.1817349065269E-22" iyy="7.69100314106116E-07" iyz="6.74715432769696E-07" izz="2.30315190420171E-06" />
        </inertial> -->
    <visual>
      <origin rpy="0 0 0" xyz="0 0 0"/>
      <geometry>
        <mesh filename="robotiq_arg2f_85_inner_finger_v.stl" scale="0.001 0.001 0.001"/>
      </geometry>
      <material name="">
        <color rgba="0.1 0.1 0.1 1"/>
      </material>
    </visual>
    <collision>
      <origin rpy="0 0 0" xyz="0 0 0"/>
      <geometry>
        <mesh filename="robotiq_arg2f_85_inner_finger.stl" scale="0.001 0.001 0.001"/>
      </geometry>
    </collision>
    <inertial>
    <origin xyz="0.00000000 -0.00782782 0.00265781"/>
    <mass value="0.00001319"/>
    <inertia ixx="0.00000000" ixy="0.00000000" ixz="-0.00000000" iyy="0.00000000" iyz="0.00000000" izz="0.00000000"/>
    </inertial>
  </link>
  <link name="left_inner_finger_pad">
    <visual>
      <origin rpy="0 0 0" xyz="0 0 0"/>
      <geometry>
        <box size="0.022 0.00635 0.0375"/>
      </geometry>
      <material name="">
        <color rgba="0.9 0.9 0.9 1"/>
      </material>
    </visual>
    <collision>
      <origin rpy="0 0 0" xyz="0 0 0"/>
      <geometry>
        <box size="0.022 0.00635 0.0375"/>
      </geometry>
      <material name="">
        <color rgba="0.9 0.0 0.0 1"/>
      </material>
    </collision>
    <inertial>
      <mass value="0.0001"/>
      <inertia ixx="0.0000001" ixy="0" ixz="0.0" iyy="0.0000001" iyz="0.0" izz="0.0000001"/>
    </inertial>
  </link>
  <link name="left_inner_knuckle">
    <!--<inertial>
        <origin xyz="0.000123011831763771 0.0507850843201817 0.00103968640075166" rpy="0 0 0" />
       <mass value="0.0271177346495152" />
        <inertia ixx="2.61910379223783E-05" ixy="-2.43616858946494E-07" ixz="-6.37789906117123E-09" iyy="2.8270243746167E-06" iyz="-5.37200748039765E-07" izz="2.83695868220296E-05" />
        </inertial> -->
    <visual>
      <origin rpy="0 0 0" xyz="0 0 0"/>
      <geometry>
        <mesh filename="robotiq_arg2f_85_inner_knuckle_v.stl" scale="0.001 0.001 0.001"/>
      </geometry>
      <material name="">
        <color rgba="0.1 0.1 0.1 1"/>
      </material>
    </visual>
    <collision>
      <origin rpy="0 0 0" xyz="0 0 0"/>
      <geometry>
        <mesh filename="robotiq_arg2f_85_inner_knuckle.stl" scale="0.001 0.001 0.001"/>
      </geometry>
    </collision>
<inertial>
  <origin xyz="-0.00000000 0.02072093 0.02448419"/>
  <mass value="0.00002731"/>
  <inertia ixx="0.00000001" ixy="0.00000000" ixz="0.00000000" iyy="0.00000001" iyz="-0.00000000" izz="0.00000001"/>
</inertial>
  </link>
  <link name="right_outer_knuckle">
    <!--<inertial>
        <origin xyz="-0.000200000000003065 0.0199435877845359 0.0292245259211331" rpy="0 0 0" />
        <mass value="0.00853198276973456" />
        <inertia ixx="2.89328108496468E-06" ixy="-1.57935047237397E-19" ixz="-1.93980378593255E-19" iyy="1.86719750325683E-06" iyz="-1.21858577871576E-06" izz="1.21905238907251E-06" />
        </inertial> -->
    <!-- <inertial>
      <mass value="0.00013"/>
      <inertia ixx="0.0000001" ixy="0.0000001" ixz="0.0000001" iyy="0.0000001" iyz="0.0000001" izz="0.0000001"/>
    </inertial> -->
    <visual>
      <origin rpy="0 0 0" xyz="0 0 0"/>
      <geometry>
        <mesh filename="robotiq_arg2f_85_outer_knuckle_v.stl" scale="0.001 0.001 0.001"/>
      </geometry>
      <material name="">
        <color rgba="0.792156862745098 0.819607843137255 0.933333333333333 1"/>
      </material>
    </visual>
    <collision>
      <origin rpy="0 0 0" xyz="0 0 0"/>
      <geometry>
        <mesh filename="robotiq_arg2f_85_outer_knuckle.stl" scale="0.001 0.001 0.001"/>
      </geometry>
    </collision>
    <inertial>
    <origin xyz="0.00000000 0.01959428 0.00167623"/>
    <mass value="0.00001294"/>
    <inertia ixx="0.00000000" ixy="0.00000000" ixz="0.00000000" iyy="0.00000000" iyz="-0.00000000" izz="0.00000000"/>
    </inertial>
  </link>
  <link name="right_outer_finger">
    <!--<inertial>
        <origin xyz="0.00030115855001899 0.0373907951953854 -0.0208027427000385" rpy="0 0 0" />
        <mass value="0.022614240507152" />
        <inertia ixx="1.52518312458174E-05" ixy="9.76583423954399E-10" ixz="-5.43838577022588E-10" iyy="6.17694243867776E-06" iyz="6.78636130740228E-06" izz="1.16494917907219E-05" />
        </inertial> -->
    <!-- <inertial>
      <mass value="0.00017"/>
      <inertia ixx="0.0000001" ixy="0.0000001" ixz="0.0000001" iyy="0.0000001" iyz="0.0000001" izz="0.0000001"/>
    </inertial> -->
    <visual>
      <origin rpy="0 0 0" xyz="0 0 0"/>
      <geometry>
        <mesh filename="robotiq_arg2f_85_outer_finger_v.stl" scale="0.001 0.001 0.001"/>
      </geometry>
      <material name="">
        <color rgba="0.1 0.1 0.1 1"/>
      </material>
    </visual>
    <collision>
      <origin rpy="0 0 0" xyz="0 0 0"/>
      <geometry>
        <mesh filename="robotiq_arg2f_85_outer_finger.stl" scale="0.001 0.001 0.001"/>
      </geometry>
    </collision>
    <inertial>
    <origin xyz="0.00000000 0.00303447 0.02345961"/>
    <mass value="0.00001778"/>
    <inertia ixx="0.00000001" ixy="-0.00000000" ixz="-0.00000000" iyy="0.00000001" iyz="-0.00000000" izz="0.00000000"/>
    </inertial>
  </link>
  <link name="right_inner_finger">
    <!--<inertial>
        <origin xyz="0.000299999999999317 0.0160078233491243 -0.0136945669206257" rpy="0 0 0" />
        <mass value="0.0104003125914103" />
        <inertia ixx="2.71909453810972E-06" ixy="1.35402465472579E-21" ixz="-7.1817349065269E-22" iyy="7.69100314106116E-07" iyz="6.74715432769696E-07" izz="2.30315190420171E-06" />
        </inertial> -->
    <visual>
      <origin rpy="0 0 0" xyz="0 0 0"/>
      <geometry>
        <mesh filename="robotiq_arg2f_85_inner_finger_v.stl" scale="0.001 0.001 0.001"/>
      </geometry>
      <material name="">
        <color rgba="0.1 0.1 0.1 1"/>
      </material>
    </visual>
    <collision>
      <origin rpy="0 0 0" xyz="0 0 0"/>
      <geometry>
        <mesh filename="robotiq_arg2f_85_inner_finger.stl" scale="0.001 0.001 0.001"/>
      </geometry>
    </collision>
    <inertial>
    <origin xyz="0.00000000 -0.00782782 0.00265781"/>
    <mass value="0.00001319"/>
    <inertia ixx="0.00000000" ixy="0.00000000" ixz="-0.00000000" iyy="0.00000000" iyz="0.00000000" izz="0.00000000"/>
    </inertial>    
  </link>
  <link name="right_inner_finger_pad">
    <visual>
      <origin rpy="0 0 0" xyz="0 0 0"/>
      <geometry>
        <box size="0.022 0.00635 0.0375"/>
      </geometry>
      <material name="">
        <color rgba="0.9 0.9 0.9 1"/>
      </material>
    </visual>
    <collision>
      <origin rpy="0 0 0" xyz="0 0 0"/>
      <geometry>
        <box size="0.022 0.00635 0.0375"/>
      </geometry>
      <material name="">
        <color rgba="0.9 0.0 0.0 1"/>
      </material>
    </collision>
    <!-- <inertial>
      <mass value="0.00013"/>
      <inertia ixx="0.0000001" ixy="0.0000001" ixz="0.0000001" iyy="0.0000001" iyz="0.0000001" izz="0.0000001"/>
    </inertial> -->
  </link>
  <link name="right_inner_knuckle">
    <!--<inertial>
        <origin xyz="0.000123011831763771 0.0507850843201817 0.00103968640075166" rpy="0 0 0" />
       <mass value="0.0271177346495152" />
        <inertia ixx="2.61910379223783E-05" ixy="-2.43616858946494E-07" ixz="-6.37789906117123E-09" iyy="2.8270243746167E-06" iyz="-5.37200748039765E-07" izz="2.83695868220296E-05" />
        </inertial> -->
    <visual>
      <origin rpy="0 0 0" xyz="0 0 0"/>
      <geometry>
        <mesh filename="robotiq_arg2f_85_inner_knuckle_v.stl" scale="0.001 0.001 0.001"/>
      </geometry>
      <material name="">
        <color rgba="0.1 0.1 0.1 1"/>
      </material>
    </visual>
    <collision>
      <origin rpy="0 0 0" xyz="0 0 0"/>
      <geometry>
        <mesh filename="robotiq_arg2f_85_inner_knuckle.stl" scale="0.001 0.001 0.001"/>
      </geometry>
    </collision>
    <inertial>
    <origin xyz="-0.00000000 0.02072093 0.02448419"/>
    <mass value="0.00002731"/>
    <inertia ixx="0.00000001" ixy="0.00000000" ixz="0.00000000" iyy="0.00000001" iyz="-0.00000000" izz="0.00000001"/>
    </inertial>
  </link>
  <!-- <joint name="finger_joint" type="revolute">
    <origin rpy="0 0 3.14159265359" xyz="0 -0.0306011 0.054904"/>
    <parent link="robotiq_arg2f_base_link"/>
    <child link="left_outer_knuckle"/>
    <axis xyz="1 0 0"/>
    <limit effort="1000" lower="0" upper="0.8" velocity="2.0"/>
  </joint> -->
  <joint name="finger_joint" type="fixed">
    <origin rpy="0 0 3.14159265359" xyz="0 -0.0306011 0.054904"/>
    <parent link="robotiq_arg2f_base_link"/>
    <child link="left_outer_knuckle"/>
    <axis xyz="1 0 0"/>
  </joint>

  <joint name="left_outer_finger_joint" type="fixed">
    <origin rpy="0 0 0" xyz="0 0.0315 -0.0041"/>
    <parent link="left_outer_knuckle"/>
    <child link="left_outer_finger"/>
    <axis xyz="1 0 0"/>
  </joint>
  <!-- <joint name="left_inner_knuckle_joint" type="revolute">
    <origin rpy="0 0 3.14159265359" xyz="0 -0.0127 0.06142"/>
    <parent link="robotiq_arg2f_base_link"/>
    <child link="left_inner_knuckle"/>
    <axis xyz="1 0 0"/>
    <limit effort="1000" lower="0" upper="0.8757" velocity="2.0"/>
    <mimic joint="finger_joint" multiplier="1" offset="0"/>
  </joint> -->
  <joint name="left_inner_knuckle_joint" type="fixed">
    <origin rpy="0 0 3.14159265359" xyz="0 -0.0127 0.06142"/>
    <parent link="robotiq_arg2f_base_link"/>
    <child link="left_inner_knuckle"/>
    <axis xyz="1 0 0"/>
    <!-- <mimic joint="finger_joint" multiplier="1" offset="0"/> -->
  </joint>


  <joint name="left_inner_finger_joint" type="fixed">
    <origin rpy="0 0 0" xyz="0 0.0061 0.0471"/>
    <parent link="left_outer_finger"/>
    <child link="left_inner_finger"/>
    <axis xyz="1 0 0"/>
    <!-- <mimic joint="finger_joint" multiplier="-1" offset="0"/> -->
  </joint>


  <!-- <joint name="left_inner_finger_joint" type="revolute">
    <origin rpy="0 0 0" xyz="0 0.0061 0.0471"/>
    <parent link="left_outer_finger"/>
    <child link="left_inner_finger"/>
    <axis xyz="1 0 0"/>
    <limit effort="1000" lower="-0.8757" upper="0" velocity="2.0"/>
    <mimic joint="finger_joint" multiplier="-1" offset="0"/>
  </joint> -->
  <joint name="left_inner_finger_pad_joint" type="fixed">
    <origin rpy="0 0 0" xyz="0 -0.0220203446692936 0.03242"/>
    <parent link="left_inner_finger"/>
    <child link="left_inner_finger_pad"/>
    <axis xyz="0 0 1"/>
  </joint>
  <joint name="right_outer_knuckle_joint" type="fixed">
    <origin rpy="0 0 0" xyz="0 0.0306011 0.054904"/>
    <parent link="robotiq_arg2f_base_link"/>
    <child link="right_outer_knuckle"/>
    <axis xyz="1 0 0"/>
    <!-- <mimic joint="finger_joint" multiplier="1" offset="0"/> -->
  </joint>
  <!-- <joint name="right_outer_knuckle_joint" type="revolute">
    <origin rpy="0 0 0" xyz="0 0.0306011 0.054904"/>
    <parent link="robotiq_arg2f_base_link"/>
    <child link="right_outer_knuckle"/>
    <axis xyz="1 0 0"/>
    <limit effort="1000" lower="0" upper="0.81" velocity="2.0"/>
    <mimic joint="finger_joint" multiplier="1" offset="0"/>
  </joint> -->
  <joint name="right_outer_finger_joint" type="fixed">
    <origin rpy="0 0 0" xyz="0 0.0315 -0.0041"/>
    <parent link="right_outer_knuckle"/>
    <child link="right_outer_finger"/>
    <axis xyz="1 0 0"/>
  </joint>
  <joint name="right_inner_knuckle_joint" type="fixed">
    <!-- <origin xyz="0 ${reflect * -0.0127} 0.06142" rpy="${pi / 2 + .725} 0 ${(reflect - 1) * pi / 2}" /> -->
    <origin rpy="0 0 0.0" xyz="0 0.0127 0.06142"/>
    <parent link="robotiq_arg2f_base_link"/>
    <child link="right_inner_knuckle"/>
    <axis xyz="1 0 0"/>
    <!-- <mimic joint="finger_joint" multiplier="1" offset="0"/> -->
  </joint>
  <!-- <joint name="right_inner_knuckle_joint" type="revolute">
    <origin rpy="0 0 0.0" xyz="0 0.0127 0.06142"/>
    <parent link="robotiq_arg2f_base_link"/>
    <child link="right_inner_knuckle"/>
    <axis xyz="1 0 0"/>
    <limit effort="1000" lower="0" upper="0.8757" velocity="2.0"/>
    <mimic joint="finger_joint" multiplier="1" offset="0"/>
  </joint> -->

  <joint name="right_inner_finger_joint" type="fixed">
    <origin rpy="0 0 0" xyz="0 0.0061 0.0471"/>
    <parent link="right_outer_finger"/>
    <child link="right_inner_finger"/>
    <axis xyz="1 0 0"/>
    <!-- <limit effort="1000" lower="-0.8757" upper="0" velocity="2.0"/> -->
    <!-- <mimic joint="finger_joint" multiplier="-1" offset="0"/> -->
  </joint>
<!-- 
  <joint name="right_inner_finger_joint" type="revolute">
    <origin rpy="0 0 0" xyz="0 0.0061 0.0471"/>
    <parent link="right_outer_finger"/>
    <child link="right_inner_finger"/>
    <axis xyz="1 0 0"/>
    <limit effort="1000" lower="-0.8757" upper="0" velocity="2.0"/>
    <mimic joint="finger_joint" multiplier="-1" offset="0"/>
  </joint> -->
  <joint name="right_inner_finger_pad_joint" type="fixed">
    <origin rpy="0 0 0" xyz="0 -0.0220203446692936 0.03242"/>
    <parent link="right_inner_finger"/>
    <child link="right_inner_finger_pad"/>
    <axis xyz="0 0 1"/>
  </joint>
  <transmission name="finger_joint_trans">
    <type>transmission_interface/SimpleTransmission</type>
    <joint name="finger_joint">
      <hardwareInterface>PositionJointInterface</hardwareInterface>
    </joint>
    <actuator name="finger_joint_motor">
      <mechanicalReduction>1</mechanicalReduction>
    </actuator>
  </transmission>


</robot>
